Workbook

Sheet Prepare Gantt Chart
B2: Fill in the 'Status' and 'Start date' columns (in light grey) for each eligeble project type. Percent coverage changes are optional; Do not make any other edits. In case you need to reset a project type, delete data in the 'Project Status' cell and write "_" (underscore) in the 'Start date' cell. | L2: Cost by sq km: (USD/sq km/Year) | AU2: ='Cost graph'!C1 -> 0 | AZ2: Annual cost: (Billion USD/Year) | BE2: ='Cost graph'!G1 -> 0 | BJ2: Annual benefit: (GtCO2e/year) | BO2: ='Cost graph'!L1 -> 0
B3: ID | F3: Project type | G3: Status | H3: Readiness | I3: Opportunity | AR3: Selection | AT3: Timing
B4: ID | C4: System ID | D4: System | E4: Code | F4: Name | G4: Status (1 = Implementation and management; 2 = Management only) | H4: Start date (starting in 2025 or later) | I4: Percent feasible in 1%, 5% or multiples of 10s% | J4: Opportunity in the current territory (sq km) | L4: Do not change or erase from this point forward | M4: Project_Start_Date (do not edit) | N4: Project_End_Date (do not edit) | O4: Project_Implementation_End_Date (2050 or before) | P4: 2025 | Q4: 2026 | R4: 2027 | S4: 2028 | T4: 2029 | U4: 2030 | V4: 2031 | W4: 2032 | X4: 2033 | Y4: 2034 | Z4: 2035 | AA4: 2036 | AB4: 2037 | AC4: 2038 | AD4: 2039 | AE4: 2040 | AF4: 2041 | AG4: 2042 | AH4: 2043 | AI4: 2044 | AJ4: 2045 | AK4: 2046 | AL4: 2047 | AM4: 2048 | AN4: 2049 | AO4: 2050 | AR4: Project Code | AT4: 2025 | AU4: 2026 | AV4: 2027 | AW4: 2028 | AX4: 2029 | AY4: 2030 | AZ4: 2031 | BA4: 2032 | BB4: 2033 | BC4: 2034 | BD4: 2035 | BE4: 2036 | BF4: 2037 | BG4: 2038 | BH4: 2039 | BI4: 2040 | BJ4: 2041 | BK4: 2042 | BL4: 2043 | BM4: 2044 | BN4: 2045 | BO4: 2046 | BP4: 2047 | BQ4: 2048 | BR4: 2049 | BS4: 2050 | BU4: Project type description
B5: 1 | C5: 1 | D5: OCEAN | E5: OCN_01 | F5: Enhance sustainable marine area conservation | H5: _ | I5: 1 | J5: 1 | M5: =H5 -> _ | N5: ='Project types'!$W$6 -> 2050 | O5: =IF(G5=1,(H5-1)+'Project types'!N6,IF(G5=2,H5-1,9999)) -> 9999 | P5: =_xlfn.IFS(AND(AND($P$4>=$H5,$P$4<=$O5)),2,AND(AND($P$4>=$M5,$P$4<=$N5)),1,AND(OR($P$4<$M5,$P$4>$N5)),0) -> 0 | Q5: =_xlfn.IFS(AND(AND($Q$4>=$H5,$Q$4<=$O5)),2,AND(AND($Q$4>=$M5,$Q$4<=$N5)),1,AND(OR($Q$4<$M5,$Q$4>$N5)),0) -> 0 | R5: =_xlfn.IFS(AND(AND($R$4>=$H5,$R$4<=$O5)),2,AND(AND($R$4>=$M5,$R$4<=$N5)),1,AND(OR($R$4<$M5,$R$4>$N5)),0) -> 0 | S5: =_xlfn.IFS(AND(AND($S$4>=$H5,$S$4<=$O5)),2,AND(AND($S$4>=$M5,$S$4<=$N5)),1,AND(OR($S$4<$M5,$S$4>$N5)),0) -> 0 | T5: =_xlfn.IFS(AND(AND($T$4>=$H5,$T$4<=$O5)),2,AND(AND($T$4>=$M5,$T$4<=$N5)),1,AND(OR($T$4<$M5,$T$4>$N5)),0) -> 0 | U5: =_xlfn.IFS(AND(AND($U$4>=$H5,$U$4<=$O5)),2,AND(AND($U$4>=$M5,$U$4<=$N5)),1,AND(OR($U$4<$M5,$U$4>$N5)),0) -> 0 | V5: =_xlfn.IFS(AND(AND($V$4>=$H5,$V$4<=$O5)),2,AND(AND($V$4>=$M5,$V$4<=$N5)),1,AND(OR($V$4<$M5,$V$4>$N5)),0) -> 0 | W5: =_xlfn.IFS(AND(AND($W$4>=$H5,$W$4<=$O5)),2,AND(AND($W$4>=$M5,$W$4<=$N5)),1,AND(OR($W$4<$M5,$W$4>$N5)),0) -> 0 | X5: =_xlfn.IFS(AND(AND($X$4>=$H5,$X$4<=$O5)),2,AND(AND($X$4>=$M5,$X$4<=$N5)),1,AND(OR($X$4<$M5,$X$4>$N5)),0) -> 0 | Y5: =_xlfn.IFS(AND(AND($Y$4>=$H5,$Y$4<=$O5)),2,AND(AND($Y$4>=$M5,$Y$4<=$N5)),1,AND(OR($Y$4<$M5,$Y$4>$N5)),0) -> 0 | Z5: =_xlfn.IFS(AND(AND($Z$4>=$H5,$Z$4<=$O5)),2,AND(AND($Z$4>=$M5,$Z$4<=$N5)),1,AND(OR($Z$4<$M5,$Z$4>$N5)),0) -> 0 | AA5: =_xlfn.IFS(AND(AND($AA$4>=$H5,$AA$4<=$O5)),2,AND(AND($AA$4>=$M5,$AA$4<=$N5)),1,AND(OR($AA$4<$M5,$AA$4>$N5)),0) -> 0 | AB5: =_xlfn.IFS(AND(AND($AB$4>=$H5,$AB$4<=$O5)),2,AND(AND($AB$4>=$M5,$AB$4<=$N5)),1,AND(OR($AB$4<$M5,$AB$4>$N5)),0) -> 0 | AC5: =_xlfn.IFS(AND(AND($AC$4>=$H5,$AC$4<=$O5)),2,AND(AND($AC$4>=$M5,$AC$4<=$N5)),1,AND(OR($AC$4<$M5,$AC$4>$N5)),0) -> 0 | AD5: =_xlfn.IFS(AND(AND($AD$4>=$H5,$AD$4<=$O5)),2,AND(AND($AD$4>=$M5,$AD$4<=$N5)),1,AND(OR($AD$4<$M5,$AD$4>$N5)),0) -> 0 | AE5: =_xlfn.IFS(AND(AND($AE$4>=$H5,$AE$4<=$O5)),2,AND(AND($AE$4>=$M5,$AE$4<=$N5)),1,AND(OR($AE$4<$M5,$AE$4>$N5)),0) -> 0 | AF5: =_xlfn.IFS(AND(AND($AF$4>=$H5,$AF$4<=$O5)),2,AND(AND($AF$4>=$M5,$AF$4<=$N5)),1,AND(OR($AF$4<$M5,$AF$4>$N5)),0) -> 0 | AG5: =_xlfn.IFS(AND(AND($AG$4>=$H5,$AG$4<=$O5)),2,AND(AND($AG$4>=$M5,$AG$4<=$N5)),1,AND(OR($AG$4<$M5,$AG$4>$N5)),0) -> 0 | AH5: =_xlfn.IFS(AND(AND($AH$4>=$H5,$AH$4<=$O5)),2,AND(AND($AH$4>=$M5,$AH$4<=$N5)),1,AND(OR($AH$4<$M5,$AH$4>$N5)),0) -> 0 | AI5: =_xlfn.IFS(AND(AND($AI$4>=$H5,$AI$4<=$O5)),2,AND(AND($AI$4>=$M5,$AI$4<=$N5)),1,AND(OR($AI$4<$M5,$AI$4>$N5)),0) -> 0 | AJ5: =_xlfn.IFS(AND(AND($AJ$4>=$H5,$AJ$4<=$O5)),2,AND(AND($AJ$4>=$M5,$AJ$4<=$N5)),1,AND(OR($AJ$4<$M5,$AJ$4>$N5)),0) -> 0 | AK5: =_xlfn.IFS(AND(AND($AK$4>=$H5,$AK$4<=$O5)),2,AND(AND($AK$4>=$M5,$AK$4<=$N5)),1,AND(OR($AK$4<$M5,$AK$4>$N5)),0) -> 0 | AL5: =_xlfn.IFS(AND(AND($AL$4>=$H5,$AL$4<=$O5)),2,AND(AND($AL$4>=$M5,$AL$4<=$N5)),1,AND(OR($AL$4<$M5,$AL$4>$N5)),0) -> 0 | AM5: =_xlfn.IFS(AND(AND($AM$4>=$H5,$AM$4<=$O5)),2,AND(AND($AM$4>=$M5,$AM$4<=$N5)),1,AND(OR($AM$4<$M5,$AM$4>$N5)),0) -> 0 | AN5: =_xlfn.IFS(AND(AND($AN$4>=$H5,$AN$4<=$O5)),2,AND(AND($AN$4>=$M5,$AN$4<=$N5)),1,AND(OR($AN$4<$M5,$AN$4>$N5)),0) -> 0 | AO5: =_xlfn.IFS(AND(AND($AO$4>=$H5,$AO$4<=$O5)),2,AND(AND($AO$4>=$M5,$AO$4<=$N5)),1,AND(OR($AO$4<$M5,$AO$4>$N5)),0) -> 0 | AQ5: 1 | AR5: OCN_01 | BU5: =#REF! -> #REF!
B6: 2 | C6: 1 | D6: OCEAN | E6: OCN_02 | F6: Enhance sustainable mangrove conservation | H6: _ | I6: 1 | J6: 1 | M6: =H6 -> _ | N6: ='Project types'!$W$6 -> 2050 | O6: =IF(G6=1,(H6-1)+'Project types'!N7,IF(G6=2,H6-1,9999)) -> 9999 | P6: =_xlfn.IFS(AND(AND($P$4>=$H6,$P$4<=$O6)),2,AND(AND($P$4>=$M6,$P$4<=$N6)),1,AND(OR($P$4<$M6,$P$4>$N6)),0) -> 0 | Q6: =_xlfn.IFS(AND(AND($Q$4>=$H6,$Q$4<=$O6)),2,AND(AND($Q$4>=$M6,$Q$4<=$N6)),1,AND(OR($Q$4<$M6,$Q$4>$N6)),0) -> 0 | R6: =_xlfn.IFS(AND(AND($R$4>=$H6,$R$4<=$O6)),2,AND(AND($R$4>=$M6,$R$4<=$N6)),1,AND(OR($R$4<$M6,$R$4>$N6)),0) -> 0 | S6: =_xlfn.IFS(AND(AND($S$4>=$H6,$S$4<=$O6)),2,AND(AND($S$4>=$M6,$S$4<=$N6)),1,AND(OR($S$4<$M6,$S$4>$N6)),0) -> 0 | T6: =_xlfn.IFS(AND(AND($T$4>=$H6,$T$4<=$O6)),2,AND(AND($T$4>=$M6,$T$4<=$N6)),1,AND(OR($T$4<$M6,$T$4>$N6)),0) -> 0 | U6: =_xlfn.IFS(AND(AND($U$4>=$H6,$U$4<=$O6)),2,AND(AND($U$4>=$M6,$U$4<=$N6)),1,AND(OR($U$4<$M6,$U$4>$N6)),0) -> 0 | V6: =_xlfn.IFS(AND(AND($V$4>=$H6,$V$4<=$O6)),2,AND(AND($V$4>=$M6,$V$4<=$N6)),1,AND(OR($V$4<$M6,$V$4>$N6)),0) -> 0 | W6: =_xlfn.IFS(AND(AND($W$4>=$H6,$W$4<=$O6)),2,AND(AND($W$4>=$M6,$W$4<=$N6)),1,AND(OR($W$4<$M6,$W$4>$N6)),0) -> 0 | X6: =_xlfn.IFS(AND(AND($X$4>=$H6,$X$4<=$O6)),2,AND(AND($X$4>=$M6,$X$4<=$N6)),1,AND(OR($X$4<$M6,$X$4>$N6)),0) -> 0 | Y6: =_xlfn.IFS(AND(AND($Y$4>=$H6,$Y$4<=$O6)),2,AND(AND($Y$4>=$M6,$Y$4<=$N6)),1,AND(OR($Y$4<$M6,$Y$4>$N6)),0) -> 0 | Z6: =_xlfn.IFS(AND(AND($Z$4>=$H6,$Z$4<=$O6)),2,AND(AND($Z$4>=$M6,$Z$4<=$N6)),1,AND(OR($Z$4<$M6,$Z$4>$N6)),0) -> 0 | AA6: =_xlfn.IFS(AND(AND($AA$4>=$H6,$AA$4<=$O6)),2,AND(AND($AA$4>=$M6,$AA$4<=$N6)),1,AND(OR($AA$4<$M6,$AA$4>$N6)),0) -> 0 | AB6: =_xlfn.IFS(AND(AND($AB$4>=$H6,$AB$4<=$O6)),2,AND(AND($AB$4>=$M6,$AB$4<=$N6)),1,AND(OR($AB$4<$M6,$AB$4>$N6)),0) -> 0 | AC6: =_xlfn.IFS(AND(AND($AC$4>=$H6,$AC$4<=$O6)),2,AND(AND($AC$4>=$M6,$AC$4<=$N6)),1,AND(OR($AC$4<$M6,$AC$4>$N6)),0) -> 0 | AD6: =_xlfn.IFS(AND(AND($AD$4>=$H6,$AD$4<=$O6)),2,AND(AND($AD$4>=$M6,$AD$4<=$N6)),1,AND(OR($AD$4<$M6,$AD$4>$N6)),0) -> 0 | AE6: =_xlfn.IFS(AND(AND($AE$4>=$H6,$AE$4<=$O6)),2,AND(AND($AE$4>=$M6,$AE$4<=$N6)),1,AND(OR($AE$4<$M6,$AE$4>$N6)),0) -> 0 | AF6: =_xlfn.IFS(AND(AND($AF$4>=$H6,$AF$4<=$O6)),2,AND(AND($AF$4>=$M6,$AF$4<=$N6)),1,AND(OR($AF$4<$M6,$AF$4>$N6)),0) -> 0 | AG6: =_xlfn.IFS(AND(AND($AG$4>=$H6,$AG$4<=$O6)),2,AND(AND($AG$4>=$M6,$AG$4<=$N6)),1,AND(OR($AG$4<$M6,$AG$4>$N6)),0) -> 0 | AH6: =_xlfn.IFS(AND(AND($AH$4>=$H6,$AH$4<=$O6)),2,AND(AND($AH$4>=$M6,$AH$4<=$N6)),1,AND(OR($AH$4<$M6,$AH$4>$N6)),0) -> 0 | AI6: =_xlfn.IFS(AND(AND($AI$4>=$H6,$AI$4<=$O6)),2,AND(AND($AI$4>=$M6,$AI$4<=$N6)),1,AND(OR($AI$4<$M6,$AI$4>$N6)),0) -> 0 | AJ6: =_xlfn.IFS(AND(AND($AJ$4>=$H6,$AJ$4<=$O6)),2,AND(AND($AJ$4>=$M6,$AJ$4<=$N6)),1,AND(OR($AJ$4<$M6,$AJ$4>$N6)),0) -> 0 | AK6: =_xlfn.IFS(AND(AND($AK$4>=$H6,$AK$4<=$O6)),2,AND(AND($AK$4>=$M6,$AK$4<=$N6)),1,AND(OR($AK$4<$M6,$AK$4>$N6)),0) -> 0 | AL6: =_xlfn.IFS(AND(AND($AL$4>=$H6,$AL$4<=$O6)),2,AND(AND($AL$4>=$M6,$AL$4<=$N6)),1,AND(OR($AL$4<$M6,$AL$4>$N6)),0) -> 0 | AM6: =_xlfn.IFS(AND(AND($AM$4>=$H6,$AM$4<=$O6)),2,AND(AND($AM$4>=$M6,$AM$4<=$N6)),1,AND(OR($AM$4<$M6,$AM$4>$N6)),0) -> 0 | AN6: =_xlfn.IFS(AND(AND($AN$4>=$H6,$AN$4<=$O6)),2,AND(AND($AN$4>=$M6,$AN$4<=$N6)),1,AND(OR($AN$4<$M6,$AN$4>$N6)),0) -> 0 | AO6: =_xlfn.IFS(AND(AND($AO$4>=$H6,$AO$4<=$O6)),2,AND(AND($AO$4>=$M6,$AO$4<=$N6)),1,AND(OR($AO$4<$M6,$AO$4>$N6)),0) -> 0 | AQ6: 1 | AR6: OCN_02 | BU6: =#REF! -> #REF!
B7: 3 | C7: 1 | D7: OCEAN | E7: OCN_03 | F7: Enhance sustainable coral reef conservation | H7: _ | I7: 1 | J7: 1 | M7: =H7 -> _ | N7: ='Project types'!$W$6 -> 2050 | O7: =IF(G7=1,(H7-1)+'Project types'!N8,IF(G7=2,H7-1,9999)) -> 9999 | P7: =_xlfn.IFS(AND(AND($P$4>=$H7,$P$4<=$O7)),2,AND(AND($P$4>=$M7,$P$4<=$N7)),1,AND(OR($P$4<$M7,$P$4>$N7)),0) -> 0 | Q7: =_xlfn.IFS(AND(AND($Q$4>=$H7,$Q$4<=$O7)),2,AND(AND($Q$4>=$M7,$Q$4<=$N7)),1,AND(OR($Q$4<$M7,$Q$4>$N7)),0) -> 0 | R7: =_xlfn.IFS(AND(AND($R$4>=$H7,$R$4<=$O7)),2,AND(AND($R$4>=$M7,$R$4<=$N7)),1,AND(OR($R$4<$M7,$R$4>$N7)),0) -> 0 | S7: =_xlfn.IFS(AND(AND($S$4>=$H7,$S$4<=$O7)),2,AND(AND($S$4>=$M7,$S$4<=$N7)),1,AND(OR($S$4<$M7,$S$4>$N7)),0) -> 0 | T7: =_xlfn.IFS(AND(AND($T$4>=$H7,$T$4<=$O7)),2,AND(AND($T$4>=$M7,$T$4<=$N7)),1,AND(OR($T$4<$M7,$T$4>$N7)),0) -> 0 | U7: =_xlfn.IFS(AND(AND($U$4>=$H7,$U$4<=$O7)),2,AND(AND($U$4>=$M7,$U$4<=$N7)),1,AND(OR($U$4<$M7,$U$4>$N7)),0) -> 0 | V7: =_xlfn.IFS(AND(AND($V$4>=$H7,$V$4<=$O7)),2,AND(AND($V$4>=$M7,$V$4<=$N7)),1,AND(OR($V$4<$M7,$V$4>$N7)),0) -> 0 | W7: =_xlfn.IFS(AND(AND($W$4>=$H7,$W$4<=$O7)),2,AND(AND($W$4>=$M7,$W$4<=$N7)),1,AND(OR($W$4<$M7,$W$4>$N7)),0) -> 0 | X7: =_xlfn.IFS(AND(AND($X$4>=$H7,$X$4<=$O7)),2,AND(AND($X$4>=$M7,$X$4<=$N7)),1,AND(OR($X$4<$M7,$X$4>$N7)),0) -> 0 | Y7: =_xlfn.IFS(AND(AND($Y$4>=$H7,$Y$4<=$O7)),2,AND(AND($Y$4>=$M7,$Y$4<=$N7)),1,AND(OR($Y$4<$M7,$Y$4>$N7)),0) -> 0 | Z7: =_xlfn.IFS(AND(AND($Z$4>=$H7,$Z$4<=$O7)),2,AND(AND($Z$4>=$M7,$Z$4<=$N7)),1,AND(OR($Z$4<$M7,$Z$4>$N7)),0) -> 0 | AA7: =_xlfn.IFS(AND(AND($AA$4>=$H7,$AA$4<=$O7)),2,AND(AND($AA$4>=$M7,$AA$4<=$N7)),1,AND(OR($AA$4<$M7,$AA$4>$N7)),0) -> 0 | AB7: =_xlfn.IFS(AND(AND($AB$4>=$H7,$AB$4<=$O7)),2,AND(AND($AB$4>=$M7,$AB$4<=$N7)),1,AND(OR($AB$4<$M7,$AB$4>$N7)),0) -> 0 | AC7: =_xlfn.IFS(AND(AND($AC$4>=$H7,$AC$4<=$O7)),2,AND(AND($AC$4>=$M7,$AC$4<=$N7)),1,AND(OR($AC$4<$M7,$AC$4>$N7)),0) -> 0 | AD7: =_xlfn.IFS(AND(AND($AD$4>=$H7,$AD$4<=$O7)),2,AND(AND($AD$4>=$M7,$AD$4<=$N7)),1,AND(OR($AD$4<$M7,$AD$4>$N7)),0) -> 0 | AE7: =_xlfn.IFS(AND(AND($AE$4>=$H7,$AE$4<=$O7)),2,AND(AND($AE$4>=$M7,$AE$4<=$N7)),1,AND(OR($AE$4<$M7,$AE$4>$N7)),0) -> 0 | AF7: =_xlfn.IFS(AND(AND($AF$4>=$H7,$AF$4<=$O7)),2,AND(AND($AF$4>=$M7,$AF$4<=$N7)),1,AND(OR($AF$4<$M7,$AF$4>$N7)),0) -> 0 | AG7: =_xlfn.IFS(AND(AND($AG$4>=$H7,$AG$4<=$O7)),2,AND(AND($AG$4>=$M7,$AG$4<=$N7)),1,AND(OR($AG$4<$M7,$AG$4>$N7)),0) -> 0 | AH7: =_xlfn.IFS(AND(AND($AH$4>=$H7,$AH$4<=$O7)),2,AND(AND($AH$4>=$M7,$AH$4<=$N7)),1,AND(OR($AH$4<$M7,$AH$4>$N7)),0) -> 0 | AI7: =_xlfn.IFS(AND(AND($AI$4>=$H7,$AI$4<=$O7)),2,AND(AND($AI$4>=$M7,$AI$4<=$N7)),1,AND(OR($AI$4<$M7,$AI$4>$N7)),0) -> 0 | AJ7: =_xlfn.IFS(AND(AND($AJ$4>=$H7,$AJ$4<=$O7)),2,AND(AND($AJ$4>=$M7,$AJ$4<=$N7)),1,AND(OR($AJ$4<$M7,$AJ$4>$N7)),0) -> 0 | AK7: =_xlfn.IFS(AND(AND($AK$4>=$H7,$AK$4<=$O7)),2,AND(AND($AK$4>=$M7,$AK$4<=$N7)),1,AND(OR($AK$4<$M7,$AK$4>$N7)),0) -> 0 | AL7: =_xlfn.IFS(AND(AND($AL$4>=$H7,$AL$4<=$O7)),2,AND(AND($AL$4>=$M7,$AL$4<=$N7)),1,AND(OR($AL$4<$M7,$AL$4>$N7)),0) -> 0 | AM7: =_xlfn.IFS(AND(AND($AM$4>=$H7,$AM$4<=$O7)),2,AND(AND($AM$4>=$M7,$AM$4<=$N7)),1,AND(OR($AM$4<$M7,$AM$4>$N7)),0) -> 0 | AN7: =_xlfn.IFS(AND(AND($AN$4>=$H7,$AN$4<=$O7)),2,AND(AND($AN$4>=$M7,$AN$4<=$N7)),1,AND(OR($AN$4<$M7,$AN$4>$N7)),0) -> 0 | AO7: =_xlfn.IFS(AND(AND($AO$4>=$H7,$AO$4<=$O7)),2,AND(AND($AO$4>=$M7,$AO$4<=$N7)),1,AND(OR($AO$4<$M7,$AO$4>$N7)),0) -> 0 | AQ7: 1 | AR7: OCN_03 | BU7: =#REF! -> #REF!
B8: 4 | C8: 1 | D8: OCEAN | E8: OCN_04 | F8: Enhance mangrove restoration | H8: _ | I8: 1 | J8: 1 | M8: =H8 -> _ | N8: ='Project types'!$W$6 -> 2050 | O8: =IF(G8=1,(H8-1)+'Project types'!N9,IF(G8=2,H8-1,9999)) -> 9999 | P8: =_xlfn.IFS(AND(AND($P$4>=$H8,$P$4<=$O8)),2,AND(AND($P$4>=$M8,$P$4<=$N8)),1,AND(OR($P$4<$M8,$P$4>$N8)),0) -> 0 | Q8: =_xlfn.IFS(AND(AND($Q$4>=$H8,$Q$4<=$O8)),2,AND(AND($Q$4>=$M8,$Q$4<=$N8)),1,AND(OR($Q$4<$M8,$Q$4>$N8)),0) -> 0 | R8: =_xlfn.IFS(AND(AND($R$4>=$H8,$R$4<=$O8)),2,AND(AND($R$4>=$M8,$R$4<=$N8)),1,AND(OR($R$4<$M8,$R$4>$N8)),0) -> 0 | S8: =_xlfn.IFS(AND(AND($S$4>=$H8,$S$4<=$O8)),2,AND(AND($S$4>=$M8,$S$4<=$N8)),1,AND(OR($S$4<$M8,$S$4>$N8)),0) -> 0 | T8: =_xlfn.IFS(AND(AND($T$4>=$H8,$T$4<=$O8)),2,AND(AND($T$4>=$M8,$T$4<=$N8)),1,AND(OR($T$4<$M8,$T$4>$N8)),0) -> 0 | U8: =_xlfn.IFS(AND(AND($U$4>=$H8,$U$4<=$O8)),2,AND(AND($U$4>=$M8,$U$4<=$N8)),1,AND(OR($U$4<$M8,$U$4>$N8)),0) -> 0 | V8: =_xlfn.IFS(AND(AND($V$4>=$H8,$V$4<=$O8)),2,AND(AND($V$4>=$M8,$V$4<=$N8)),1,AND(OR($V$4<$M8,$V$4>$N8)),0) -> 0 | W8: =_xlfn.IFS(AND(AND($W$4>=$H8,$W$4<=$O8)),2,AND(AND($W$4>=$M8,$W$4<=$N8)),1,AND(OR($W$4<$M8,$W$4>$N8)),0) -> 0 | X8: =_xlfn.IFS(AND(AND($X$4>=$H8,$X$4<=$O8)),2,AND(AND($X$4>=$M8,$X$4<=$N8)),1,AND(OR($X$4<$M8,$X$4>$N8)),0) -> 0 | Y8: =_xlfn.IFS(AND(AND($Y$4>=$H8,$Y$4<=$O8)),2,AND(AND($Y$4>=$M8,$Y$4<=$N8)),1,AND(OR($Y$4<$M8,$Y$4>$N8)),0) -> 0 | Z8: =_xlfn.IFS(AND(AND($Z$4>=$H8,$Z$4<=$O8)),2,AND(AND($Z$4>=$M8,$Z$4<=$N8)),1,AND(OR($Z$4<$M8,$Z$4>$N8)),0) -> 0 | AA8: =_xlfn.IFS(AND(AND($AA$4>=$H8,$AA$4<=$O8)),2,AND(AND($AA$4>=$M8,$AA$4<=$N8)),1,AND(OR($AA$4<$M8,$AA$4>$N8)),0) -> 0 | AB8: =_xlfn.IFS(AND(AND($AB$4>=$H8,$AB$4<=$O8)),2,AND(AND($AB$4>=$M8,$AB$4<=$N8)),1,AND(OR($AB$4<$M8,$AB$4>$N8)),0) -> 0 | AC8: =_xlfn.IFS(AND(AND($AC$4>=$H8,$AC$4<=$O8)),2,AND(AND($AC$4>=$M8,$AC$4<=$N8)),1,AND(OR($AC$4<$M8,$AC$4>$N8)),0) -> 0 | AD8: =_xlfn.IFS(AND(AND($AD$4>=$H8,$AD$4<=$O8)),2,AND(AND($AD$4>=$M8,$AD$4<=$N8)),1,AND(OR($AD$4<$M8,$AD$4>$N8)),0) -> 0 | AE8: =_xlfn.IFS(AND(AND($AE$4>=$H8,$AE$4<=$O8)),2,AND(AND($AE$4>=$M8,$AE$4<=$N8)),1,AND(OR($AE$4<$M8,$AE$4>$N8)),0) -> 0 | AF8: =_xlfn.IFS(AND(AND($AF$4>=$H8,$AF$4<=$O8)),2,AND(AND($AF$4>=$M8,$AF$4<=$N8)),1,AND(OR($AF$4<$M8,$AF$4>$N8)),0) -> 0 | AG8: =_xlfn.IFS(AND(AND($AG$4>=$H8,$AG$4<=$O8)),2,AND(AND($AG$4>=$M8,$AG$4<=$N8)),1,AND(OR($AG$4<$M8,$AG$4>$N8)),0) -> 0 | AH8: =_xlfn.IFS(AND(AND($AH$4>=$H8,$AH$4<=$O8)),2,AND(AND($AH$4>=$M8,$AH$4<=$N8)),1,AND(OR($AH$4<$M8,$AH$4>$N8)),0) -> 0 | AI8: =_xlfn.IFS(AND(AND($AI$4>=$H8,$AI$4<=$O8)),2,AND(AND($AI$4>=$M8,$AI$4<=$N8)),1,AND(OR($AI$4<$M8,$AI$4>$N8)),0) -> 0 | AJ8: =_xlfn.IFS(AND(AND($AJ$4>=$H8,$AJ$4<=$O8)),2,AND(AND($AJ$4>=$M8,$AJ$4<=$N8)),1,AND(OR($AJ$4<$M8,$AJ$4>$N8)),0) -> 0 | AK8: =_xlfn.IFS(AND(AND($AK$4>=$H8,$AK$4<=$O8)),2,AND(AND($AK$4>=$M8,$AK$4<=$N8)),1,AND(OR($AK$4<$M8,$AK$4>$N8)),0) -> 0 | AL8: =_xlfn.IFS(AND(AND($AL$4>=$H8,$AL$4<=$O8)),2,AND(AND($AL$4>=$M8,$AL$4<=$N8)),1,AND(OR($AL$4<$M8,$AL$4>$N8)),0) -> 0 | AM8: =_xlfn.IFS(AND(AND($AM$4>=$H8,$AM$4<=$O8)),2,AND(AND($AM$4>=$M8,$AM$4<=$N8)),1,AND(OR($AM$4<$M8,$AM$4>$N8)),0) -> 0 | AN8: =_xlfn.IFS(AND(AND($AN$4>=$H8,$AN$4<=$O8)),2,AND(AND($AN$4>=$M8,$AN$4<=$N8)),1,AND(OR($AN$4<$M8,$AN$4>$N8)),0) -> 0 | AO8: =_xlfn.IFS(AND(AND($AO$4>=$H8,$AO$4<=$O8)),2,AND(AND($AO$4>=$M8,$AO$4<=$N8)),1,AND(OR($AO$4<$M8,$AO$4>$N8)),0) -> 0 | AQ8: 1 | AR8: OCN_04 | BU8: =#REF! -> #REF!
B9: 5 | C9: 1 | D9: OCEAN | E9: OCN_05 | F9: Enhance coral reef restoration | H9: _ | I9: 1 | J9: 1 | M9: =H9 -> _ | N9: ='Project types'!$W$6 -> 2050 | O9: =IF(G9=1,(H9-1)+'Project types'!N10,IF(G9=2,H9-1,9999)) -> 9999 | P9: =_xlfn.IFS(AND(AND($P$4>=$H9,$P$4<=$O9)),2,AND(AND($P$4>=$M9,$P$4<=$N9)),1,AND(OR($P$4<$M9,$P$4>$N9)),0) -> 0 | Q9: =_xlfn.IFS(AND(AND($Q$4>=$H9,$Q$4<=$O9)),2,AND(AND($Q$4>=$M9,$Q$4<=$N9)),1,AND(OR($Q$4<$M9,$Q$4>$N9)),0) -> 0 | R9: =_xlfn.IFS(AND(AND($R$4>=$H9,$R$4<=$O9)),2,AND(AND($R$4>=$M9,$R$4<=$N9)),1,AND(OR($R$4<$M9,$R$4>$N9)),0) -> 0 | S9: =_xlfn.IFS(AND(AND($S$4>=$H9,$S$4<=$O9)),2,AND(AND($S$4>=$M9,$S$4<=$N9)),1,AND(OR($S$4<$M9,$S$4>$N9)),0) -> 0 | T9: =_xlfn.IFS(AND(AND($T$4>=$H9,$T$4<=$O9)),2,AND(AND($T$4>=$M9,$T$4<=$N9)),1,AND(OR($T$4<$M9,$T$4>$N9)),0) -> 0 | U9: =_xlfn.IFS(AND(AND($U$4>=$H9,$U$4<=$O9)),2,AND(AND($U$4>=$M9,$U$4<=$N9)),1,AND(OR($U$4<$M9,$U$4>$N9)),0) -> 0 | V9: =_xlfn.IFS(AND(AND($V$4>=$H9,$V$4<=$O9)),2,AND(AND($V$4>=$M9,$V$4<=$N9)),1,AND(OR($V$4<$M9,$V$4>$N9)),0) -> 0 | W9: =_xlfn.IFS(AND(AND($W$4>=$H9,$W$4<=$O9)),2,AND(AND($W$4>=$M9,$W$4<=$N9)),1,AND(OR($W$4<$M9,$W$4>$N9)),0) -> 0 | X9: =_xlfn.IFS(AND(AND($X$4>=$H9,$X$4<=$O9)),2,AND(AND($X$4>=$M9,$X$4<=$N9)),1,AND(OR($X$4<$M9,$X$4>$N9)),0) -> 0 | Y9: =_xlfn.IFS(AND(AND($Y$4>=$H9,$Y$4<=$O9)),2,AND(AND($Y$4>=$M9,$Y$4<=$N9)),1,AND(OR($Y$4<$M9,$Y$4>$N9)),0) -> 0 | Z9: =_xlfn.IFS(AND(AND($Z$4>=$H9,$Z$4<=$O9)),2,AND(AND($Z$4>=$M9,$Z$4<=$N9)),1,AND(OR($Z$4<$M9,$Z$4>$N9)),0) -> 0 | AA9: =_xlfn.IFS(AND(AND($AA$4>=$H9,$AA$4<=$O9)),2,AND(AND($AA$4>=$M9,$AA$4<=$N9)),1,AND(OR($AA$4<$M9,$AA$4>$N9)),0) -> 0 | AB9: =_xlfn.IFS(AND(AND($AB$4>=$H9,$AB$4<=$O9)),2,AND(AND($AB$4>=$M9,$AB$4<=$N9)),1,AND(OR($AB$4<$M9,$AB$4>$N9)),0) -> 0 | AC9: =_xlfn.IFS(AND(AND($AC$4>=$H9,$AC$4<=$O9)),2,AND(AND($AC$4>=$M9,$AC$4<=$N9)),1,AND(OR($AC$4<$M9,$AC$4>$N9)),0) -> 0 | AD9: =_xlfn.IFS(AND(AND($AD$4>=$H9,$AD$4<=$O9)),2,AND(AND($AD$4>=$M9,$AD$4<=$N9)),1,AND(OR($AD$4<$M9,$AD$4>$N9)),0) -> 0 | AE9: =_xlfn.IFS(AND(AND($AE$4>=$H9,$AE$4<=$O9)),2,AND(AND($AE$4>=$M9,$AE$4<=$N9)),1,AND(OR($AE$4<$M9,$AE$4>$N9)),0) -> 0 | AF9: =_xlfn.IFS(AND(AND($AF$4>=$H9,$AF$4<=$O9)),2,AND(AND($AF$4>=$M9,$AF$4<=$N9)),1,AND(OR($AF$4<$M9,$AF$4>$N9)),0) -> 0 | AG9: =_xlfn.IFS(AND(AND($AG$4>=$H9,$AG$4<=$O9)),2,AND(AND($AG$4>=$M9,$AG$4<=$N9)),1,AND(OR($AG$4<$M9,$AG$4>$N9)),0) -> 0 | AH9: =_xlfn.IFS(AND(AND($AH$4>=$H9,$AH$4<=$O9)),2,AND(AND($AH$4>=$M9,$AH$4<=$N9)),1,AND(OR($AH$4<$M9,$AH$4>$N9)),0) -> 0 | AI9: =_xlfn.IFS(AND(AND($AI$4>=$H9,$AI$4<=$O9)),2,AND(AND($AI$4>=$M9,$AI$4<=$N9)),1,AND(OR($AI$4<$M9,$AI$4>$N9)),0) -> 0 | AJ9: =_xlfn.IFS(AND(AND($AJ$4>=$H9,$AJ$4<=$O9)),2,AND(AND($AJ$4>=$M9,$AJ$4<=$N9)),1,AND(OR($AJ$4<$M9,$AJ$4>$N9)),0) -> 0 | AK9: =_xlfn.IFS(AND(AND($AK$4>=$H9,$AK$4<=$O9)),2,AND(AND($AK$4>=$M9,$AK$4<=$N9)),1,AND(OR($AK$4<$M9,$AK$4>$N9)),0) -> 0 | AL9: =_xlfn.IFS(AND(AND($AL$4>=$H9,$AL$4<=$O9)),2,AND(AND($AL$4>=$M9,$AL$4<=$N9)),1,AND(OR($AL$4<$M9,$AL$4>$N9)),0) -> 0 | AM9: =_xlfn.IFS(AND(AND($AM$4>=$H9,$AM$4<=$O9)),2,AND(AND($AM$4>=$M9,$AM$4<=$N9)),1,AND(OR($AM$4<$M9,$AM$4>$N9)),0) -> 0 | AN9: =_xlfn.IFS(AND(AND($AN$4>=$H9,$AN$4<=$O9)),2,AND(AND($AN$4>=$M9,$AN$4<=$N9)),1,AND(OR($AN$4<$M9,$AN$4>$N9)),0) -> 0 | AO9: =_xlfn.IFS(AND(AND($AO$4>=$H9,$AO$4<=$O9)),2,AND(AND($AO$4>=$M9,$AO$4<=$N9)),1,AND(OR($AO$4<$M9,$AO$4>$N9)),0) -> 0 | AQ9: 1 | AR9: OCN_05 | BU9: =#REF! -> #REF!
B10: 6 | C10: 1 | D10: OCEAN | E10: OCN_06 | F10: Enhance sustainable fishing | H10: _ | I10: 0.01 | J10: 1 | M10: =H10 -> _ | N10: ='Project types'!$W$6 -> 2050 | O10: =IF(G10=1,(H10-1)+'Project types'!N11,IF(G10=2,H10-1,9999)) -> 9999 | P10: =_xlfn.IFS(AND(AND($P$4>=$H10,$P$4<=$O10)),2,AND(AND($P$4>=$M10,$P$4<=$N10)),1,AND(OR($P$4<$M10,$P$4>$N10)),0) -> 0 | Q10: =_xlfn.IFS(AND(AND($Q$4>=$H10,$Q$4<=$O10)),2,AND(AND($Q$4>=$M10,$Q$4<=$N10)),1,AND(OR($Q$4<$M10,$Q$4>$N10)),0) -> 0 | R10: =_xlfn.IFS(AND(AND($R$4>=$H10,$R$4<=$O10)),2,AND(AND($R$4>=$M10,$R$4<=$N10)),1,AND(OR($R$4<$M10,$R$4>$N10)),0) -> 0 | S10: =_xlfn.IFS(AND(AND($S$4>=$H10,$S$4<=$O10)),2,AND(AND($S$4>=$M10,$S$4<=$N10)),1,AND(OR($S$4<$M10,$S$4>$N10)),0) -> 0 | T10: =_xlfn.IFS(AND(AND($T$4>=$H10,$T$4<=$O10)),2,AND(AND($T$4>=$M10,$T$4<=$N10)),1,AND(OR($T$4<$M10,$T$4>$N10)),0) -> 0 | U10: =_xlfn.IFS(AND(AND($U$4>=$H10,$U$4<=$O10)),2,AND(AND($U$4>=$M10,$U$4<=$N10)),1,AND(OR($U$4<$M10,$U$4>$N10)),0) -> 0 | V10: =_xlfn.IFS(AND(AND($V$4>=$H10,$V$4<=$O10)),2,AND(AND($V$4>=$M10,$V$4<=$N10)),1,AND(OR($V$4<$M10,$V$4>$N10)),0) -> 0 | W10: =_xlfn.IFS(AND(AND($W$4>=$H10,$W$4<=$O10)),2,AND(AND($W$4>=$M10,$W$4<=$N10)),1,AND(OR($W$4<$M10,$W$4>$N10)),0) -> 0 | X10: =_xlfn.IFS(AND(AND($X$4>=$H10,$X$4<=$O10)),2,AND(AND($X$4>=$M10,$X$4<=$N10)),1,AND(OR($X$4<$M10,$X$4>$N10)),0) -> 0 | Y10: =_xlfn.IFS(AND(AND($Y$4>=$H10,$Y$4<=$O10)),2,AND(AND($Y$4>=$M10,$Y$4<=$N10)),1,AND(OR($Y$4<$M10,$Y$4>$N10)),0) -> 0 | Z10: =_xlfn.IFS(AND(AND($Z$4>=$H10,$Z$4<=$O10)),2,AND(AND($Z$4>=$M10,$Z$4<=$N10)),1,AND(OR($Z$4<$M10,$Z$4>$N10)),0) -> 0 | AA10: =_xlfn.IFS(AND(AND($AA$4>=$H10,$AA$4<=$O10)),2,AND(AND($AA$4>=$M10,$AA$4<=$N10)),1,AND(OR($AA$4<$M10,$AA$4>$N10)),0) -> 0 | AB10: =_xlfn.IFS(AND(AND($AB$4>=$H10,$AB$4<=$O10)),2,AND(AND($AB$4>=$M10,$AB$4<=$N10)),1,AND(OR($AB$4<$M10,$AB$4>$N10)),0) -> 0 | AC10: =_xlfn.IFS(AND(AND($AC$4>=$H10,$AC$4<=$O10)),2,AND(AND($AC$4>=$M10,$AC$4<=$N10)),1,AND(OR($AC$4<$M10,$AC$4>$N10)),0) -> 0 | AD10: =_xlfn.IFS(AND(AND($AD$4>=$H10,$AD$4<=$O10)),2,AND(AND($AD$4>=$M10,$AD$4<=$N10)),1,AND(OR($AD$4<$M10,$AD$4>$N10)),0) -> 0 | AE10: =_xlfn.IFS(AND(AND($AE$4>=$H10,$AE$4<=$O10)),2,AND(AND($AE$4>=$M10,$AE$4<=$N10)),1,AND(OR($AE$4<$M10,$AE$4>$N10)),0) -> 0 | AF10: =_xlfn.IFS(AND(AND($AF$4>=$H10,$AF$4<=$O10)),2,AND(AND($AF$4>=$M10,$AF$4<=$N10)),1,AND(OR($AF$4<$M10,$AF$4>$N10)),0) -> 0 | AG10: =_xlfn.IFS(AND(AND($AG$4>=$H10,$AG$4<=$O10)),2,AND(AND($AG$4>=$M10,$AG$4<=$N10)),1,AND(OR($AG$4<$M10,$AG$4>$N10)),0) -> 0 | AH10: =_xlfn.IFS(AND(AND($AH$4>=$H10,$AH$4<=$O10)),2,AND(AND($AH$4>=$M10,$AH$4<=$N10)),1,AND(OR($AH$4<$M10,$AH$4>$N10)),0) -> 0 | AI10: =_xlfn.IFS(AND(AND($AI$4>=$H10,$AI$4<=$O10)),2,AND(AND($AI$4>=$M10,$AI$4<=$N10)),1,AND(OR($AI$4<$M10,$AI$4>$N10)),0) -> 0 | AJ10: =_xlfn.IFS(AND(AND($AJ$4>=$H10,$AJ$4<=$O10)),2,AND(AND($AJ$4>=$M10,$AJ$4<=$N10)),1,AND(OR($AJ$4<$M10,$AJ$4>$N10)),0) -> 0 | AK10: =_xlfn.IFS(AND(AND($AK$4>=$H10,$AK$4<=$O10)),2,AND(AND($AK$4>=$M10,$AK$4<=$N10)),1,AND(OR($AK$4<$M10,$AK$4>$N10)),0) -> 0 | AL10: =_xlfn.IFS(AND(AND($AL$4>=$H10,$AL$4<=$O10)),2,AND(AND($AL$4>=$M10,$AL$4<=$N10)),1,AND(OR($AL$4<$M10,$AL$4>$N10)),0) -> 0 | AM10: =_xlfn.IFS(AND(AND($AM$4>=$H10,$AM$4<=$O10)),2,AND(AND($AM$4>=$M10,$AM$4<=$N10)),1,AND(OR($AM$4<$M10,$AM$4>$N10)),0) -> 0 | AN10: =_xlfn.IFS(AND(AND($AN$4>=$H10,$AN$4<=$O10)),2,AND(AND($AN$4>=$M10,$AN$4<=$N10)),1,AND(OR($AN$4<$M10,$AN$4>$N10)),0) -> 0 | AO10: =_xlfn.IFS(AND(AND($AO$4>=$H10,$AO$4<=$O10)),2,AND(AND($AO$4>=$M10,$AO$4<=$N10)),1,AND(OR($AO$4<$M10,$AO$4>$N10)),0) -> 0 | AQ10: 1 | AR10: OCN_06 | BU10: =#REF! -> #REF!
B11: 7 | C11: 1 | D11: OCEAN | E11: OCN_07 | F11: Enhance ocean fertilization | H11: _ | I11: 0.01 | J11: 1 | M11: =H11 -> _ | N11: ='Project types'!$W$6 -> 2050 | O11: =IF(G11=1,(H11-1)+'Project types'!N12,IF(G11=2,H11-1,9999)) -> 9999 | P11: =_xlfn.IFS(AND(AND($P$4>=$H11,$P$4<=$O11)),2,AND(AND($P$4>=$M11,$P$4<=$N11)),1,AND(OR($P$4<$M11,$P$4>$N11)),0) -> 0 | Q11: =_xlfn.IFS(AND(AND($Q$4>=$H11,$Q$4<=$O11)),2,AND(AND($Q$4>=$M11,$Q$4<=$N11)),1,AND(OR($Q$4<$M11,$Q$4>$N11)),0) -> 0 | R11: =_xlfn.IFS(AND(AND($R$4>=$H11,$R$4<=$O11)),2,AND(AND($R$4>=$M11,$R$4<=$N11)),1,AND(OR($R$4<$M11,$R$4>$N11)),0) -> 0 | S11: =_xlfn.IFS(AND(AND($S$4>=$H11,$S$4<=$O11)),2,AND(AND($S$4>=$M11,$S$4<=$N11)),1,AND(OR($S$4<$M11,$S$4>$N11)),0) -> 0 | T11: =_xlfn.IFS(AND(AND($T$4>=$H11,$T$4<=$O11)),2,AND(AND($T$4>=$M11,$T$4<=$N11)),1,AND(OR($T$4<$M11,$T$4>$N11)),0) -> 0 | U11: =_xlfn.IFS(AND(AND($U$4>=$H11,$U$4<=$O11)),2,AND(AND($U$4>=$M11,$U$4<=$N11)),1,AND(OR($U$4<$M11,$U$4>$N11)),0) -> 0 | V11: =_xlfn.IFS(AND(AND($V$4>=$H11,$V$4<=$O11)),2,AND(AND($V$4>=$M11,$V$4<=$N11)),1,AND(OR($V$4<$M11,$V$4>$N11)),0) -> 0 | W11: =_xlfn.IFS(AND(AND($W$4>=$H11,$W$4<=$O11)),2,AND(AND($W$4>=$M11,$W$4<=$N11)),1,AND(OR($W$4<$M11,$W$4>$N11)),0) -> 0 | X11: =_xlfn.IFS(AND(AND($X$4>=$H11,$X$4<=$O11)),2,AND(AND($X$4>=$M11,$X$4<=$N11)),1,AND(OR($X$4<$M11,$X$4>$N11)),0) -> 0 | Y11: =_xlfn.IFS(AND(AND($Y$4>=$H11,$Y$4<=$O11)),2,AND(AND($Y$4>=$M11,$Y$4<=$N11)),1,AND(OR($Y$4<$M11,$Y$4>$N11)),0) -> 0 | Z11: =_xlfn.IFS(AND(AND($Z$4>=$H11,$Z$4<=$O11)),2,AND(AND($Z$4>=$M11,$Z$4<=$N11)),1,AND(OR($Z$4<$M11,$Z$4>$N11)),0) -> 0 | AA11: =_xlfn.IFS(AND(AND($AA$4>=$H11,$AA$4<=$O11)),2,AND(AND($AA$4>=$M11,$AA$4<=$N11)),1,AND(OR($AA$4<$M11,$AA$4>$N11)),0) -> 0 | AB11: =_xlfn.IFS(AND(AND($AB$4>=$H11,$AB$4<=$O11)),2,AND(AND($AB$4>=$M11,$AB$4<=$N11)),1,AND(OR($AB$4<$M11,$AB$4>$N11)),0) -> 0 | AC11: =_xlfn.IFS(AND(AND($AC$4>=$H11,$AC$4<=$O11)),2,AND(AND($AC$4>=$M11,$AC$4<=$N11)),1,AND(OR($AC$4<$M11,$AC$4>$N11)),0) -> 0 | AD11: =_xlfn.IFS(AND(AND($AD$4>=$H11,$AD$4<=$O11)),2,AND(AND($AD$4>=$M11,$AD$4<=$N11)),1,AND(OR($AD$4<$M11,$AD$4>$N11)),0) -> 0 | AE11: =_xlfn.IFS(AND(AND($AE$4>=$H11,$AE$4<=$O11)),2,AND(AND($AE$4>=$M11,$AE$4<=$N11)),1,AND(OR($AE$4<$M11,$AE$4>$N11)),0) -> 0 | AF11: =_xlfn.IFS(AND(AND($AF$4>=$H11,$AF$4<=$O11)),2,AND(AND($AF$4>=$M11,$AF$4<=$N11)),1,AND(OR($AF$4<$M11,$AF$4>$N11)),0) -> 0 | AG11: =_xlfn.IFS(AND(AND($AG$4>=$H11,$AG$4<=$O11)),2,AND(AND($AG$4>=$M11,$AG$4<=$N11)),1,AND(OR($AG$4<$M11,$AG$4>$N11)),0) -> 0 | AH11: =_xlfn.IFS(AND(AND($AH$4>=$H11,$AH$4<=$O11)),2,AND(AND($AH$4>=$M11,$AH$4<=$N11)),1,AND(OR($AH$4<$M11,$AH$4>$N11)),0) -> 0 | AI11: =_xlfn.IFS(AND(AND($AI$4>=$H11,$AI$4<=$O11)),2,AND(AND($AI$4>=$M11,$AI$4<=$N11)),1,AND(OR($AI$4<$M11,$AI$4>$N11)),0) -> 0 | AJ11: =_xlfn.IFS(AND(AND($AJ$4>=$H11,$AJ$4<=$O11)),2,AND(AND($AJ$4>=$M11,$AJ$4<=$N11)),1,AND(OR($AJ$4<$M11,$AJ$4>$N11)),0) -> 0 | AK11: =_xlfn.IFS(AND(AND($AK$4>=$H11,$AK$4<=$O11)),2,AND(AND($AK$4>=$M11,$AK$4<=$N11)),1,AND(OR($AK$4<$M11,$AK$4>$N11)),0) -> 0 | AL11: =_xlfn.IFS(AND(AND($AL$4>=$H11,$AL$4<=$O11)),2,AND(AND($AL$4>=$M11,$AL$4<=$N11)),1,AND(OR($AL$4<$M11,$AL$4>$N11)),0) -> 0 | AM11: =_xlfn.IFS(AND(AND($AM$4>=$H11,$AM$4<=$O11)),2,AND(AND($AM$4>=$M11,$AM$4<=$N11)),1,AND(OR($AM$4<$M11,$AM$4>$N11)),0) -> 0 | AN11: =_xlfn.IFS(AND(AND($AN$4>=$H11,$AN$4<=$O11)),2,AND(AND($AN$4>=$M11,$AN$4<=$N11)),1,AND(OR($AN$4<$M11,$AN$4>$N11)),0) -> 0 | AO11: =_xlfn.IFS(AND(AND($AO$4>=$H11,$AO$4<=$O11)),2,AND(AND($AO$4>=$M11,$AO$4<=$N11)),1,AND(OR($AO$4<$M11,$AO$4>$N11)),0) -> 0 | AQ11: 1 | AR11: OCN_07 | BU11: =#REF! -> #REF!
B12: 8 | C12: 1 | D12: OCEAN | E12: OCN_08 | F12: Enhance repopulating overfished area | H12: _ | I12: 0.01 | J12: 1 | M12: =H12 -> _ | N12: ='Project types'!$W$6 -> 2050 | O12: =IF(G12=1,(H12-1)+'Project types'!N13,IF(G12=2,H12-1,9999)) -> 9999 | P12: =_xlfn.IFS(AND(AND($P$4>=$H12,$P$4<=$O12)),2,AND(AND($P$4>=$M12,$P$4<=$N12)),1,AND(OR($P$4<$M12,$P$4>$N12)),0) -> 0 | Q12: =_xlfn.IFS(AND(AND($Q$4>=$H12,$Q$4<=$O12)),2,AND(AND($Q$4>=$M12,$Q$4<=$N12)),1,AND(OR($Q$4<$M12,$Q$4>$N12)),0) -> 0 | R12: =_xlfn.IFS(AND(AND($R$4>=$H12,$R$4<=$O12)),2,AND(AND($R$4>=$M12,$R$4<=$N12)),1,AND(OR($R$4<$M12,$R$4>$N12)),0) -> 0 | S12: =_xlfn.IFS(AND(AND($S$4>=$H12,$S$4<=$O12)),2,AND(AND($S$4>=$M12,$S$4<=$N12)),1,AND(OR($S$4<$M12,$S$4>$N12)),0) -> 0 | T12: =_xlfn.IFS(AND(AND($T$4>=$H12,$T$4<=$O12)),2,AND(AND($T$4>=$M12,$T$4<=$N12)),1,AND(OR($T$4<$M12,$T$4>$N12)),0) -> 0 | U12: =_xlfn.IFS(AND(AND($U$4>=$H12,$U$4<=$O12)),2,AND(AND($U$4>=$M12,$U$4<=$N12)),1,AND(OR($U$4<$M12,$U$4>$N12)),0) -> 0 | V12: =_xlfn.IFS(AND(AND($V$4>=$H12,$V$4<=$O12)),2,AND(AND($V$4>=$M12,$V$4<=$N12)),1,AND(OR($V$4<$M12,$V$4>$N12)),0) -> 0 | W12: =_xlfn.IFS(AND(AND($W$4>=$H12,$W$4<=$O12)),2,AND(AND($W$4>=$M12,$W$4<=$N12)),1,AND(OR($W$4<$M12,$W$4>$N12)),0) -> 0 | X12: =_xlfn.IFS(AND(AND($X$4>=$H12,$X$4<=$O12)),2,AND(AND($X$4>=$M12,$X$4<=$N12)),1,AND(OR($X$4<$M12,$X$4>$N12)),0) -> 0 | Y12: =_xlfn.IFS(AND(AND($Y$4>=$H12,$Y$4<=$O12)),2,AND(AND($Y$4>=$M12,$Y$4<=$N12)),1,AND(OR($Y$4<$M12,$Y$4>$N12)),0) -> 0 | Z12: =_xlfn.IFS(AND(AND($Z$4>=$H12,$Z$4<=$O12)),2,AND(AND($Z$4>=$M12,$Z$4<=$N12)),1,AND(OR($Z$4<$M12,$Z$4>$N12)),0) -> 0 | AA12: =_xlfn.IFS(AND(AND($AA$4>=$H12,$AA$4<=$O12)),2,AND(AND($AA$4>=$M12,$AA$4<=$N12)),1,AND(OR($AA$4<$M12,$AA$4>$N12)),0) -> 0 | AB12: =_xlfn.IFS(AND(AND($AB$4>=$H12,$AB$4<=$O12)),2,AND(AND($AB$4>=$M12,$AB$4<=$N12)),1,AND(OR($AB$4<$M12,$AB$4>$N12)),0) -> 0 | AC12: =_xlfn.IFS(AND(AND($AC$4>=$H12,$AC$4<=$O12)),2,AND(AND($AC$4>=$M12,$AC$4<=$N12)),1,AND(OR($AC$4<$M12,$AC$4>$N12)),0) -> 0 | AD12: =_xlfn.IFS(AND(AND($AD$4>=$H12,$AD$4<=$O12)),2,AND(AND($AD$4>=$M12,$AD$4<=$N12)),1,AND(OR($AD$4<$M12,$AD$4>$N12)),0) -> 0 | AE12: =_xlfn.IFS(AND(AND($AE$4>=$H12,$AE$4<=$O12)),2,AND(AND($AE$4>=$M12,$AE$4<=$N12)),1,AND(OR($AE$4<$M12,$AE$4>$N12)),0) -> 0 | AF12: =_xlfn.IFS(AND(AND($AF$4>=$H12,$AF$4<=$O12)),2,AND(AND($AF$4>=$M12,$AF$4<=$N12)),1,AND(OR($AF$4<$M12,$AF$4>$N12)),0) -> 0 | AG12: =_xlfn.IFS(AND(AND($AG$4>=$H12,$AG$4<=$O12)),2,AND(AND($AG$4>=$M12,$AG$4<=$N12)),1,AND(OR($AG$4<$M12,$AG$4>$N12)),0) -> 0 | AH12: =_xlfn.IFS(AND(AND($AH$4>=$H12,$AH$4<=$O12)),2,AND(AND($AH$4>=$M12,$AH$4<=$N12)),1,AND(OR($AH$4<$M12,$AH$4>$N12)),0) -> 0 | AI12: =_xlfn.IFS(AND(AND($AI$4>=$H12,$AI$4<=$O12)),2,AND(AND($AI$4>=$M12,$AI$4<=$N12)),1,AND(OR($AI$4<$M12,$AI$4>$N12)),0) -> 0 | AJ12: =_xlfn.IFS(AND(AND($AJ$4>=$H12,$AJ$4<=$O12)),2,AND(AND($AJ$4>=$M12,$AJ$4<=$N12)),1,AND(OR($AJ$4<$M12,$AJ$4>$N12)),0) -> 0 | AK12: =_xlfn.IFS(AND(AND($AK$4>=$H12,$AK$4<=$O12)),2,AND(AND($AK$4>=$M12,$AK$4<=$N12)),1,AND(OR($AK$4<$M12,$AK$4>$N12)),0) -> 0 | AL12: =_xlfn.IFS(AND(AND($AL$4>=$H12,$AL$4<=$O12)),2,AND(AND($AL$4>=$M12,$AL$4<=$N12)),1,AND(OR($AL$4<$M12,$AL$4>$N12)),0) -> 0 | AM12: =_xlfn.IFS(AND(AND($AM$4>=$H12,$AM$4<=$O12)),2,AND(AND($AM$4>=$M12,$AM$4<=$N12)),1,AND(OR($AM$4<$M12,$AM$4>$N12)),0) -> 0 | AN12: =_xlfn.IFS(AND(AND($AN$4>=$H12,$AN$4<=$O12)),2,AND(AND($AN$4>=$M12,$AN$4<=$N12)),1,AND(OR($AN$4<$M12,$AN$4>$N12)),0) -> 0 | AO12: =_xlfn.IFS(AND(AND($AO$4>=$H12,$AO$4<=$O12)),2,AND(AND($AO$4>=$M12,$AO$4<=$N12)),1,AND(OR($AO$4<$M12,$AO$4>$N12)),0) -> 0 | AQ12: 1 | AR12: OCN_08 | BU12: =#REF! -> #REF!
B13: 9 | C13: 1 | D13: OCEAN | E13: OCN_09 | F13: Enhance sustainable aquaculture management | H13: _ | I13: 0.01 | J13: 1 | M13: =H13 -> _ | N13: ='Project types'!$W$6 -> 2050 | O13: =IF(G13=1,(H13-1)+'Project types'!N14,IF(G13=2,H13-1,9999)) -> 9999 | P13: =_xlfn.IFS(AND(AND($P$4>=$H13,$P$4<=$O13)),2,AND(AND($P$4>=$M13,$P$4<=$N13)),1,AND(OR($P$4<$M13,$P$4>$N13)),0) -> 0 | Q13: =_xlfn.IFS(AND(AND($Q$4>=$H13,$Q$4<=$O13)),2,AND(AND($Q$4>=$M13,$Q$4<=$N13)),1,AND(OR($Q$4<$M13,$Q$4>$N13)),0) -> 0 | R13: =_xlfn.IFS(AND(AND($R$4>=$H13,$R$4<=$O13)),2,AND(AND($R$4>=$M13,$R$4<=$N13)),1,AND(OR($R$4<$M13,$R$4>$N13)),0) -> 0 | S13: =_xlfn.IFS(AND(AND($S$4>=$H13,$S$4<=$O13)),2,AND(AND($S$4>=$M13,$S$4<=$N13)),1,AND(OR($S$4<$M13,$S$4>$N13)),0) -> 0 | T13: =_xlfn.IFS(AND(AND($T$4>=$H13,$T$4<=$O13)),2,AND(AND($T$4>=$M13,$T$4<=$N13)),1,AND(OR($T$4<$M13,$T$4>$N13)),0) -> 0 | U13: =_xlfn.IFS(AND(AND($U$4>=$H13,$U$4<=$O13)),2,AND(AND($U$4>=$M13,$U$4<=$N13)),1,AND(OR($U$4<$M13,$U$4>$N13)),0) -> 0 | V13: =_xlfn.IFS(AND(AND($V$4>=$H13,$V$4<=$O13)),2,AND(AND($V$4>=$M13,$V$4<=$N13)),1,AND(OR($V$4<$M13,$V$4>$N13)),0) -> 0 | W13: =_xlfn.IFS(AND(AND($W$4>=$H13,$W$4<=$O13)),2,AND(AND($W$4>=$M13,$W$4<=$N13)),1,AND(OR($W$4<$M13,$W$4>$N13)),0) -> 0 | X13: =_xlfn.IFS(AND(AND($X$4>=$H13,$X$4<=$O13)),2,AND(AND($X$4>=$M13,$X$4<=$N13)),1,AND(OR($X$4<$M13,$X$4>$N13)),0) -> 0 | Y13: =_xlfn.IFS(AND(AND($Y$4>=$H13,$Y$4<=$O13)),2,AND(AND($Y$4>=$M13,$Y$4<=$N13)),1,AND(OR($Y$4<$M13,$Y$4>$N13)),0) -> 0 | Z13: =_xlfn.IFS(AND(AND($Z$4>=$H13,$Z$4<=$O13)),2,AND(AND($Z$4>=$M13,$Z$4<=$N13)),1,AND(OR($Z$4<$M13,$Z$4>$N13)),0) -> 0 | AA13: =_xlfn.IFS(AND(AND($AA$4>=$H13,$AA$4<=$O13)),2,AND(AND($AA$4>=$M13,$AA$4<=$N13)),1,AND(OR($AA$4<$M13,$AA$4>$N13)),0) -> 0 | AB13: =_xlfn.IFS(AND(AND($AB$4>=$H13,$AB$4<=$O13)),2,AND(AND($AB$4>=$M13,$AB$4<=$N13)),1,AND(OR($AB$4<$M13,$AB$4>$N13)),0) -> 0 | AC13: =_xlfn.IFS(AND(AND($AC$4>=$H13,$AC$4<=$O13)),2,AND(AND($AC$4>=$M13,$AC$4<=$N13)),1,AND(OR($AC$4<$M13,$AC$4>$N13)),0) -> 0 | AD13: =_xlfn.IFS(AND(AND($AD$4>=$H13,$AD$4<=$O13)),2,AND(AND($AD$4>=$M13,$AD$4<=$N13)),1,AND(OR($AD$4<$M13,$AD$4>$N13)),0) -> 0 | AE13: =_xlfn.IFS(AND(AND($AE$4>=$H13,$AE$4<=$O13)),2,AND(AND($AE$4>=$M13,$AE$4<=$N13)),1,AND(OR($AE$4<$M13,$AE$4>$N13)),0) -> 0 | AF13: =_xlfn.IFS(AND(AND($AF$4>=$H13,$AF$4<=$O13)),2,AND(AND($AF$4>=$M13,$AF$4<=$N13)),1,AND(OR($AF$4<$M13,$AF$4>$N13)),0) -> 0 | AG13: =_xlfn.IFS(AND(AND($AG$4>=$H13,$AG$4<=$O13)),2,AND(AND($AG$4>=$M13,$AG$4<=$N13)),1,AND(OR($AG$4<$M13,$AG$4>$N13)),0) -> 0 | AH13: =_xlfn.IFS(AND(AND($AH$4>=$H13,$AH$4<=$O13)),2,AND(AND($AH$4>=$M13,$AH$4<=$N13)),1,AND(OR($AH$4<$M13,$AH$4>$N13)),0) -> 0 | AI13: =_xlfn.IFS(AND(AND($AI$4>=$H13,$AI$4<=$O13)),2,AND(AND($AI$4>=$M13,$AI$4<=$N13)),1,AND(OR($AI$4<$M13,$AI$4>$N13)),0) -> 0 | AJ13: =_xlfn.IFS(AND(AND($AJ$4>=$H13,$AJ$4<=$O13)),2,AND(AND($AJ$4>=$M13,$AJ$4<=$N13)),1,AND(OR($AJ$4<$M13,$AJ$4>$N13)),0) -> 0 | AK13: =_xlfn.IFS(AND(AND($AK$4>=$H13,$AK$4<=$O13)),2,AND(AND($AK$4>=$M13,$AK$4<=$N13)),1,AND(OR($AK$4<$M13,$AK$4>$N13)),0) -> 0 | AL13: =_xlfn.IFS(AND(AND($AL$4>=$H13,$AL$4<=$O13)),2,AND(AND($AL$4>=$M13,$AL$4<=$N13)),1,AND(OR($AL$4<$M13,$AL$4>$N13)),0) -> 0 | AM13: =_xlfn.IFS(AND(AND($AM$4>=$H13,$AM$4<=$O13)),2,AND(AND($AM$4>=$M13,$AM$4<=$N13)),1,AND(OR($AM$4<$M13,$AM$4>$N13)),0) -> 0 | AN13: =_xlfn.IFS(AND(AND($AN$4>=$H13,$AN$4<=$O13)),2,AND(AND($AN$4>=$M13,$AN$4<=$N13)),1,AND(OR($AN$4<$M13,$AN$4>$N13)),0) -> 0 | AO13: =_xlfn.IFS(AND(AND($AO$4>=$H13,$AO$4<=$O13)),2,AND(AND($AO$4>=$M13,$AO$4<=$N13)),1,AND(OR($AO$4<$M13,$AO$4>$N13)),0) -> 0 | AQ13: 1 | AR13: OCN_09 | BU13: =#REF! -> #REF!
B14: 10 | C14: 1 | D14: OCEAN | E14: OCN_10 | F14: Eliminate shipping pollution | H14: _ | I14: 1 | J14: 1 | M14: =H14 -> _ | N14: ='Project types'!$W$6 -> 2050 | O14: =IF(G14=1,(H14-1)+'Project types'!N15,IF(G14=2,H14-1,9999)) -> 9999 | P14: =_xlfn.IFS(AND(AND($P$4>=$H14,$P$4<=$O14)),2,AND(AND($P$4>=$M14,$P$4<=$N14)),1,AND(OR($P$4<$M14,$P$4>$N14)),0) -> 0 | Q14: =_xlfn.IFS(AND(AND($Q$4>=$H14,$Q$4<=$O14)),2,AND(AND($Q$4>=$M14,$Q$4<=$N14)),1,AND(OR($Q$4<$M14,$Q$4>$N14)),0) -> 0 | R14: =_xlfn.IFS(AND(AND($R$4>=$H14,$R$4<=$O14)),2,AND(AND($R$4>=$M14,$R$4<=$N14)),1,AND(OR($R$4<$M14,$R$4>$N14)),0) -> 0 | S14: =_xlfn.IFS(AND(AND($S$4>=$H14,$S$4<=$O14)),2,AND(AND($S$4>=$M14,$S$4<=$N14)),1,AND(OR($S$4<$M14,$S$4>$N14)),0) -> 0 | T14: =_xlfn.IFS(AND(AND($T$4>=$H14,$T$4<=$O14)),2,AND(AND($T$4>=$M14,$T$4<=$N14)),1,AND(OR($T$4<$M14,$T$4>$N14)),0) -> 0 | U14: =_xlfn.IFS(AND(AND($U$4>=$H14,$U$4<=$O14)),2,AND(AND($U$4>=$M14,$U$4<=$N14)),1,AND(OR($U$4<$M14,$U$4>$N14)),0) -> 0 | V14: =_xlfn.IFS(AND(AND($V$4>=$H14,$V$4<=$O14)),2,AND(AND($V$4>=$M14,$V$4<=$N14)),1,AND(OR($V$4<$M14,$V$4>$N14)),0) -> 0 | W14: =_xlfn.IFS(AND(AND($W$4>=$H14,$W$4<=$O14)),2,AND(AND($W$4>=$M14,$W$4<=$N14)),1,AND(OR($W$4<$M14,$W$4>$N14)),0) -> 0 | X14: =_xlfn.IFS(AND(AND($X$4>=$H14,$X$4<=$O14)),2,AND(AND($X$4>=$M14,$X$4<=$N14)),1,AND(OR($X$4<$M14,$X$4>$N14)),0) -> 0 | Y14: =_xlfn.IFS(AND(AND($Y$4>=$H14,$Y$4<=$O14)),2,AND(AND($Y$4>=$M14,$Y$4<=$N14)),1,AND(OR($Y$4<$M14,$Y$4>$N14)),0) -> 0 | Z14: =_xlfn.IFS(AND(AND($Z$4>=$H14,$Z$4<=$O14)),2,AND(AND($Z$4>=$M14,$Z$4<=$N14)),1,AND(OR($Z$4<$M14,$Z$4>$N14)),0) -> 0 | AA14: =_xlfn.IFS(AND(AND($AA$4>=$H14,$AA$4<=$O14)),2,AND(AND($AA$4>=$M14,$AA$4<=$N14)),1,AND(OR($AA$4<$M14,$AA$4>$N14)),0) -> 0 | AB14: =_xlfn.IFS(AND(AND($AB$4>=$H14,$AB$4<=$O14)),2,AND(AND($AB$4>=$M14,$AB$4<=$N14)),1,AND(OR($AB$4<$M14,$AB$4>$N14)),0) -> 0 | AC14: =_xlfn.IFS(AND(AND($AC$4>=$H14,$AC$4<=$O14)),2,AND(AND($AC$4>=$M14,$AC$4<=$N14)),1,AND(OR($AC$4<$M14,$AC$4>$N14)),0) -> 0 | AD14: =_xlfn.IFS(AND(AND($AD$4>=$H14,$AD$4<=$O14)),2,AND(AND($AD$4>=$M14,$AD$4<=$N14)),1,AND(OR($AD$4<$M14,$AD$4>$N14)),0) -> 0 | AE14: =_xlfn.IFS(AND(AND($AE$4>=$H14,$AE$4<=$O14)),2,AND(AND($AE$4>=$M14,$AE$4<=$N14)),1,AND(OR($AE$4<$M14,$AE$4>$N14)),0) -> 0 | AF14: =_xlfn.IFS(AND(AND($AF$4>=$H14,$AF$4<=$O14)),2,AND(AND($AF$4>=$M14,$AF$4<=$N14)),1,AND(OR($AF$4<$M14,$AF$4>$N14)),0) -> 0 | AG14: =_xlfn.IFS(AND(AND($AG$4>=$H14,$AG$4<=$O14)),2,AND(AND($AG$4>=$M14,$AG$4<=$N14)),1,AND(OR($AG$4<$M14,$AG$4>$N14)),0) -> 0 | AH14: =_xlfn.IFS(AND(AND($AH$4>=$H14,$AH$4<=$O14)),2,AND(AND($AH$4>=$M14,$AH$4<=$N14)),1,AND(OR($AH$4<$M14,$AH$4>$N14)),0) -> 0 | AI14: =_xlfn.IFS(AND(AND($AI$4>=$H14,$AI$4<=$O14)),2,AND(AND($AI$4>=$M14,$AI$4<=$N14)),1,AND(OR($AI$4<$M14,$AI$4>$N14)),0) -> 0 | AJ14: =_xlfn.IFS(AND(AND($AJ$4>=$H14,$AJ$4<=$O14)),2,AND(AND($AJ$4>=$M14,$AJ$4<=$N14)),1,AND(OR($AJ$4<$M14,$AJ$4>$N14)),0) -> 0 | AK14: =_xlfn.IFS(AND(AND($AK$4>=$H14,$AK$4<=$O14)),2,AND(AND($AK$4>=$M14,$AK$4<=$N14)),1,AND(OR($AK$4<$M14,$AK$4>$N14)),0) -> 0 | AL14: =_xlfn.IFS(AND(AND($AL$4>=$H14,$AL$4<=$O14)),2,AND(AND($AL$4>=$M14,$AL$4<=$N14)),1,AND(OR($AL$4<$M14,$AL$4>$N14)),0) -> 0 | AM14: =_xlfn.IFS(AND(AND($AM$4>=$H14,$AM$4<=$O14)),2,AND(AND($AM$4>=$M14,$AM$4<=$N14)),1,AND(OR($AM$4<$M14,$AM$4>$N14)),0) -> 0 | AN14: =_xlfn.IFS(AND(AND($AN$4>=$H14,$AN$4<=$O14)),2,AND(AND($AN$4>=$M14,$AN$4<=$N14)),1,AND(OR($AN$4<$M14,$AN$4>$N14)),0) -> 0 | AO14: =_xlfn.IFS(AND(AND($AO$4>=$H14,$AO$4<=$O14)),2,AND(AND($AO$4>=$M14,$AO$4<=$N14)),1,AND(OR($AO$4<$M14,$AO$4>$N14)),0) -> 0 | AQ14: 1 | AR14: OCN_10 | BU14: =#REF! -> #REF!
B15: 11 | C15: 1 | D15: OCEAN | E15: OCN_11 | F15: Limit bottom trawling | H15: _ | I15: 1 | J15: 1 | M15: =H15 -> _ | N15: ='Project types'!$W$6 -> 2050 | O15: =IF(G15=1,(H15-1)+'Project types'!N16,IF(G15=2,H15-1,9999)) -> 9999 | P15: =_xlfn.IFS(AND(AND($P$4>=$H15,$P$4<=$O15)),2,AND(AND($P$4>=$M15,$P$4<=$N15)),1,AND(OR($P$4<$M15,$P$4>$N15)),0) -> 0 | Q15: =_xlfn.IFS(AND(AND($Q$4>=$H15,$Q$4<=$O15)),2,AND(AND($Q$4>=$M15,$Q$4<=$N15)),1,AND(OR($Q$4<$M15,$Q$4>$N15)),0) -> 0 | R15: =_xlfn.IFS(AND(AND($R$4>=$H15,$R$4<=$O15)),2,AND(AND($R$4>=$M15,$R$4<=$N15)),1,AND(OR($R$4<$M15,$R$4>$N15)),0) -> 0 | S15: =_xlfn.IFS(AND(AND($S$4>=$H15,$S$4<=$O15)),2,AND(AND($S$4>=$M15,$S$4<=$N15)),1,AND(OR($S$4<$M15,$S$4>$N15)),0) -> 0 | T15: =_xlfn.IFS(AND(AND($T$4>=$H15,$T$4<=$O15)),2,AND(AND($T$4>=$M15,$T$4<=$N15)),1,AND(OR($T$4<$M15,$T$4>$N15)),0) -> 0 | U15: =_xlfn.IFS(AND(AND($U$4>=$H15,$U$4<=$O15)),2,AND(AND($U$4>=$M15,$U$4<=$N15)),1,AND(OR($U$4<$M15,$U$4>$N15)),0) -> 0 | V15: =_xlfn.IFS(AND(AND($V$4>=$H15,$V$4<=$O15)),2,AND(AND($V$4>=$M15,$V$4<=$N15)),1,AND(OR($V$4<$M15,$V$4>$N15)),0) -> 0 | W15: =_xlfn.IFS(AND(AND($W$4>=$H15,$W$4<=$O15)),2,AND(AND($W$4>=$M15,$W$4<=$N15)),1,AND(OR($W$4<$M15,$W$4>$N15)),0) -> 0 | X15: =_xlfn.IFS(AND(AND($X$4>=$H15,$X$4<=$O15)),2,AND(AND($X$4>=$M15,$X$4<=$N15)),1,AND(OR($X$4<$M15,$X$4>$N15)),0) -> 0 | Y15: =_xlfn.IFS(AND(AND($Y$4>=$H15,$Y$4<=$O15)),2,AND(AND($Y$4>=$M15,$Y$4<=$N15)),1,AND(OR($Y$4<$M15,$Y$4>$N15)),0) -> 0 | Z15: =_xlfn.IFS(AND(AND($Z$4>=$H15,$Z$4<=$O15)),2,AND(AND($Z$4>=$M15,$Z$4<=$N15)),1,AND(OR($Z$4<$M15,$Z$4>$N15)),0) -> 0 | AA15: =_xlfn.IFS(AND(AND($AA$4>=$H15,$AA$4<=$O15)),2,AND(AND($AA$4>=$M15,$AA$4<=$N15)),1,AND(OR($AA$4<$M15,$AA$4>$N15)),0) -> 0 | AB15: =_xlfn.IFS(AND(AND($AB$4>=$H15,$AB$4<=$O15)),2,AND(AND($AB$4>=$M15,$AB$4<=$N15)),1,AND(OR($AB$4<$M15,$AB$4>$N15)),0) -> 0 | AC15: =_xlfn.IFS(AND(AND($AC$4>=$H15,$AC$4<=$O15)),2,AND(AND($AC$4>=$M15,$AC$4<=$N15)),1,AND(OR($AC$4<$M15,$AC$4>$N15)),0) -> 0 | AD15: =_xlfn.IFS(AND(AND($AD$4>=$H15,$AD$4<=$O15)),2,AND(AND($AD$4>=$M15,$AD$4<=$N15)),1,AND(OR($AD$4<$M15,$AD$4>$N15)),0) -> 0 | AE15: =_xlfn.IFS(AND(AND($AE$4>=$H15,$AE$4<=$O15)),2,AND(AND($AE$4>=$M15,$AE$4<=$N15)),1,AND(OR($AE$4<$M15,$AE$4>$N15)),0) -> 0 | AF15: =_xlfn.IFS(AND(AND($AF$4>=$H15,$AF$4<=$O15)),2,AND(AND($AF$4>=$M15,$AF$4<=$N15)),1,AND(OR($AF$4<$M15,$AF$4>$N15)),0) -> 0 | AG15: =_xlfn.IFS(AND(AND($AG$4>=$H15,$AG$4<=$O15)),2,AND(AND($AG$4>=$M15,$AG$4<=$N15)),1,AND(OR($AG$4<$M15,$AG$4>$N15)),0) -> 0 | AH15: =_xlfn.IFS(AND(AND($AH$4>=$H15,$AH$4<=$O15)),2,AND(AND($AH$4>=$M15,$AH$4<=$N15)),1,AND(OR($AH$4<$M15,$AH$4>$N15)),0) -> 0 | AI15: =_xlfn.IFS(AND(AND($AI$4>=$H15,$AI$4<=$O15)),2,AND(AND($AI$4>=$M15,$AI$4<=$N15)),1,AND(OR($AI$4<$M15,$AI$4>$N15)),0) -> 0 | AJ15: =_xlfn.IFS(AND(AND($AJ$4>=$H15,$AJ$4<=$O15)),2,AND(AND($AJ$4>=$M15,$AJ$4<=$N15)),1,AND(OR($AJ$4<$M15,$AJ$4>$N15)),0) -> 0 | AK15: =_xlfn.IFS(AND(AND($AK$4>=$H15,$AK$4<=$O15)),2,AND(AND($AK$4>=$M15,$AK$4<=$N15)),1,AND(OR($AK$4<$M15,$AK$4>$N15)),0) -> 0 | AL15: =_xlfn.IFS(AND(AND($AL$4>=$H15,$AL$4<=$O15)),2,AND(AND($AL$4>=$M15,$AL$4<=$N15)),1,AND(OR($AL$4<$M15,$AL$4>$N15)),0) -> 0 | AM15: =_xlfn.IFS(AND(AND($AM$4>=$H15,$AM$4<=$O15)),2,AND(AND($AM$4>=$M15,$AM$4<=$N15)),1,AND(OR($AM$4<$M15,$AM$4>$N15)),0) -> 0 | AN15: =_xlfn.IFS(AND(AND($AN$4>=$H15,$AN$4<=$O15)),2,AND(AND($AN$4>=$M15,$AN$4<=$N15)),1,AND(OR($AN$4<$M15,$AN$4>$N15)),0) -> 0 | AO15: =_xlfn.IFS(AND(AND($AO$4>=$H15,$AO$4<=$O15)),2,AND(AND($AO$4>=$M15,$AO$4<=$N15)),1,AND(OR($AO$4<$M15,$AO$4>$N15)),0) -> 0 | AQ15: 1 | AR15: OCN_11 | BU15: =#REF! -> #REF!
B16: 12 | C16: 1 | D16: OCEAN | E16: OCN_12 | F16: Adopt carbon taxation for emissions, benefits for sequestration | H16: _ | I16: 0.01 | J16: 1 | M16: =H16 -> _ | N16: ='Project types'!$W$6 -> 2050 | O16: =IF(G16=1,(H16-1)+'Project types'!N17,IF(G16=2,H16-1,9999)) -> 9999 | P16: =_xlfn.IFS(AND(AND($P$4>=$H16,$P$4<=$O16)),2,AND(AND($P$4>=$M16,$P$4<=$N16)),1,AND(OR($P$4<$M16,$P$4>$N16)),0) -> 0 | Q16: =_xlfn.IFS(AND(AND($Q$4>=$H16,$Q$4<=$O16)),2,AND(AND($Q$4>=$M16,$Q$4<=$N16)),1,AND(OR($Q$4<$M16,$Q$4>$N16)),0) -> 0 | R16: =_xlfn.IFS(AND(AND($R$4>=$H16,$R$4<=$O16)),2,AND(AND($R$4>=$M16,$R$4<=$N16)),1,AND(OR($R$4<$M16,$R$4>$N16)),0) -> 0 | S16: =_xlfn.IFS(AND(AND($S$4>=$H16,$S$4<=$O16)),2,AND(AND($S$4>=$M16,$S$4<=$N16)),1,AND(OR($S$4<$M16,$S$4>$N16)),0) -> 0 | T16: =_xlfn.IFS(AND(AND($T$4>=$H16,$T$4<=$O16)),2,AND(AND($T$4>=$M16,$T$4<=$N16)),1,AND(OR($T$4<$M16,$T$4>$N16)),0) -> 0 | U16: =_xlfn.IFS(AND(AND($U$4>=$H16,$U$4<=$O16)),2,AND(AND($U$4>=$M16,$U$4<=$N16)),1,AND(OR($U$4<$M16,$U$4>$N16)),0) -> 0 | V16: =_xlfn.IFS(AND(AND($V$4>=$H16,$V$4<=$O16)),2,AND(AND($V$4>=$M16,$V$4<=$N16)),1,AND(OR($V$4<$M16,$V$4>$N16)),0) -> 0 | W16: =_xlfn.IFS(AND(AND($W$4>=$H16,$W$4<=$O16)),2,AND(AND($W$4>=$M16,$W$4<=$N16)),1,AND(OR($W$4<$M16,$W$4>$N16)),0) -> 0 | X16: =_xlfn.IFS(AND(AND($X$4>=$H16,$X$4<=$O16)),2,AND(AND($X$4>=$M16,$X$4<=$N16)),1,AND(OR($X$4<$M16,$X$4>$N16)),0) -> 0 | Y16: =_xlfn.IFS(AND(AND($Y$4>=$H16,$Y$4<=$O16)),2,AND(AND($Y$4>=$M16,$Y$4<=$N16)),1,AND(OR($Y$4<$M16,$Y$4>$N16)),0) -> 0 | Z16: =_xlfn.IFS(AND(AND($Z$4>=$H16,$Z$4<=$O16)),2,AND(AND($Z$4>=$M16,$Z$4<=$N16)),1,AND(OR($Z$4<$M16,$Z$4>$N16)),0) -> 0 | AA16: =_xlfn.IFS(AND(AND($AA$4>=$H16,$AA$4<=$O16)),2,AND(AND($AA$4>=$M16,$AA$4<=$N16)),1,AND(OR($AA$4<$M16,$AA$4>$N16)),0) -> 0 | AB16: =_xlfn.IFS(AND(AND($AB$4>=$H16,$AB$4<=$O16)),2,AND(AND($AB$4>=$M16,$AB$4<=$N16)),1,AND(OR($AB$4<$M16,$AB$4>$N16)),0) -> 0 | AC16: =_xlfn.IFS(AND(AND($AC$4>=$H16,$AC$4<=$O16)),2,AND(AND($AC$4>=$M16,$AC$4<=$N16)),1,AND(OR($AC$4<$M16,$AC$4>$N16)),0) -> 0 | AD16: =_xlfn.IFS(AND(AND($AD$4>=$H16,$AD$4<=$O16)),2,AND(AND($AD$4>=$M16,$AD$4<=$N16)),1,AND(OR($AD$4<$M16,$AD$4>$N16)),0) -> 0 | AE16: =_xlfn.IFS(AND(AND($AE$4>=$H16,$AE$4<=$O16)),2,AND(AND($AE$4>=$M16,$AE$4<=$N16)),1,AND(OR($AE$4<$M16,$AE$4>$N16)),0) -> 0 | AF16: =_xlfn.IFS(AND(AND($AF$4>=$H16,$AF$4<=$O16)),2,AND(AND($AF$4>=$M16,$AF$4<=$N16)),1,AND(OR($AF$4<$M16,$AF$4>$N16)),0) -> 0 | AG16: =_xlfn.IFS(AND(AND($AG$4>=$H16,$AG$4<=$O16)),2,AND(AND($AG$4>=$M16,$AG$4<=$N16)),1,AND(OR($AG$4<$M16,$AG$4>$N16)),0) -> 0 | AH16: =_xlfn.IFS(AND(AND($AH$4>=$H16,$AH$4<=$O16)),2,AND(AND($AH$4>=$M16,$AH$4<=$N16)),1,AND(OR($AH$4<$M16,$AH$4>$N16)),0) -> 0 | AI16: =_xlfn.IFS(AND(AND($AI$4>=$H16,$AI$4<=$O16)),2,AND(AND($AI$4>=$M16,$AI$4<=$N16)),1,AND(OR($AI$4<$M16,$AI$4>$N16)),0) -> 0 | AJ16: =_xlfn.IFS(AND(AND($AJ$4>=$H16,$AJ$4<=$O16)),2,AND(AND($AJ$4>=$M16,$AJ$4<=$N16)),1,AND(OR($AJ$4<$M16,$AJ$4>$N16)),0) -> 0 | AK16: =_xlfn.IFS(AND(AND($AK$4>=$H16,$AK$4<=$O16)),2,AND(AND($AK$4>=$M16,$AK$4<=$N16)),1,AND(OR($AK$4<$M16,$AK$4>$N16)),0) -> 0 | AL16: =_xlfn.IFS(AND(AND($AL$4>=$H16,$AL$4<=$O16)),2,AND(AND($AL$4>=$M16,$AL$4<=$N16)),1,AND(OR($AL$4<$M16,$AL$4>$N16)),0) -> 0 | AM16: =_xlfn.IFS(AND(AND($AM$4>=$H16,$AM$4<=$O16)),2,AND(AND($AM$4>=$M16,$AM$4<=$N16)),1,AND(OR($AM$4<$M16,$AM$4>$N16)),0) -> 0 | AN16: =_xlfn.IFS(AND(AND($AN$4>=$H16,$AN$4<=$O16)),2,AND(AND($AN$4>=$M16,$AN$4<=$N16)),1,AND(OR($AN$4<$M16,$AN$4>$N16)),0) -> 0 | AO16: =_xlfn.IFS(AND(AND($AO$4>=$H16,$AO$4<=$O16)),2,AND(AND($AO$4>=$M16,$AO$4<=$N16)),1,AND(OR($AO$4<$M16,$AO$4>$N16)),0) -> 0 | AQ16: 1 | AR16: OCN_12 | BU16: =#REF! -> #REF!
B17: 13 | C17: 2 | D17: WATER | E17: WAT_01 | F17: Enhance sustainable wetland conservation | H17: _ | I17: 1 | J17: 1 | M17: =H17 -> _ | N17: ='Project types'!$W$6 -> 2050 | O17: =IF(G17=1,(H17-1)+'Project types'!N18,IF(G17=2,H17-1,9999)) -> 9999 | P17: =_xlfn.IFS(AND(AND($P$4>=$H17,$P$4<=$O17)),4,AND(AND($P$4>=$M17,$P$4<=$N17)),3,AND(OR($P$4<$M17,$P$4>$N17)),0) -> 0 | Q17: =_xlfn.IFS(AND(AND($Q$4>=$H17,$Q$4<=$O17)),4,AND(AND($Q$4>=$M17,$Q$4<=$N17)),3,AND(OR($Q$4<$M17,$Q$4>$N17)),0) -> 0 | R17: =_xlfn.IFS(AND(AND($R$4>=$H17,$R$4<=$O17)),4,AND(AND($R$4>=$M17,$R$4<=$N17)),3,AND(OR($R$4<$M17,$R$4>$N17)),0) -> 0 | S17: =_xlfn.IFS(AND(AND($S$4>=$H17,$S$4<=$O17)),4,AND(AND($S$4>=$M17,$S$4<=$N17)),3,AND(OR($S$4<$M17,$S$4>$N17)),0) -> 0 | T17: =_xlfn.IFS(AND(AND($T$4>=$H17,$T$4<=$O17)),4,AND(AND($T$4>=$M17,$T$4<=$N17)),3,AND(OR($T$4<$M17,$T$4>$N17)),0) -> 0 | U17: =_xlfn.IFS(AND(AND($U$4>=$H17,$U$4<=$O17)),4,AND(AND($U$4>=$M17,$U$4<=$N17)),3,AND(OR($U$4<$M17,$U$4>$N17)),0) -> 0 | V17: =_xlfn.IFS(AND(AND($V$4>=$H17,$V$4<=$O17)),4,AND(AND($V$4>=$M17,$V$4<=$N17)),3,AND(OR($V$4<$M17,$V$4>$N17)),0) -> 0 | W17: =_xlfn.IFS(AND(AND($W$4>=$H17,$W$4<=$O17)),4,AND(AND($W$4>=$M17,$W$4<=$N17)),3,AND(OR($W$4<$M17,$W$4>$N17)),0) -> 0 | X17: =_xlfn.IFS(AND(AND($X$4>=$H17,$X$4<=$O17)),4,AND(AND($X$4>=$M17,$X$4<=$N17)),3,AND(OR($X$4<$M17,$X$4>$N17)),0) -> 0 | Y17: =_xlfn.IFS(AND(AND($Y$4>=$H17,$Y$4<=$O17)),4,AND(AND($Y$4>=$M17,$Y$4<=$N17)),3,AND(OR($Y$4<$M17,$Y$4>$N17)),0) -> 0 | Z17: =_xlfn.IFS(AND(AND($Z$4>=$H17,$Z$4<=$O17)),4,AND(AND($Z$4>=$M17,$Z$4<=$N17)),3,AND(OR($Z$4<$M17,$Z$4>$N17)),0) -> 0 | AA17: =_xlfn.IFS(AND(AND($AA$4>=$H17,$AA$4<=$O17)),4,AND(AND($AA$4>=$M17,$AA$4<=$N17)),3,AND(OR($AA$4<$M17,$AA$4>$N17)),0) -> 0 | AB17: =_xlfn.IFS(AND(AND($AB$4>=$H17,$AB$4<=$O17)),4,AND(AND($AB$4>=$M17,$AB$4<=$N17)),3,AND(OR($AB$4<$M17,$AB$4>$N17)),0) -> 0 | AC17: =_xlfn.IFS(AND(AND($AC$4>=$H17,$AC$4<=$O17)),4,AND(AND($AC$4>=$M17,$AC$4<=$N17)),3,AND(OR($AC$4<$M17,$AC$4>$N17)),0) -> 0 | AD17: =_xlfn.IFS(AND(AND($AD$4>=$H17,$AD$4<=$O17)),4,AND(AND($AD$4>=$M17,$AD$4<=$N17)),3,AND(OR($AD$4<$M17,$AD$4>$N17)),0) -> 0 | AE17: =_xlfn.IFS(AND(AND($AE$4>=$H17,$AE$4<=$O17)),4,AND(AND($AE$4>=$M17,$AE$4<=$N17)),3,AND(OR($AE$4<$M17,$AE$4>$N17)),0) -> 0 | AF17: =_xlfn.IFS(AND(AND($AF$4>=$H17,$AF$4<=$O17)),4,AND(AND($AF$4>=$M17,$AF$4<=$N17)),3,AND(OR($AF$4<$M17,$AF$4>$N17)),0) -> 0 | AG17: =_xlfn.IFS(AND(AND($AG$4>=$H17,$AG$4<=$O17)),4,AND(AND($AG$4>=$M17,$AG$4<=$N17)),3,AND(OR($AG$4<$M17,$AG$4>$N17)),0) -> 0 | AH17: =_xlfn.IFS(AND(AND($AH$4>=$H17,$AH$4<=$O17)),4,AND(AND($AH$4>=$M17,$AH$4<=$N17)),3,AND(OR($AH$4<$M17,$AH$4>$N17)),0) -> 0 | AI17: =_xlfn.IFS(AND(AND($AI$4>=$H17,$AI$4<=$O17)),4,AND(AND($AI$4>=$M17,$AI$4<=$N17)),3,AND(OR($AI$4<$M17,$AI$4>$N17)),0) -> 0 | AJ17: =_xlfn.IFS(AND(AND($AJ$4>=$H17,$AJ$4<=$O17)),4,AND(AND($AJ$4>=$M17,$AJ$4<=$N17)),3,AND(OR($AJ$4<$M17,$AJ$4>$N17)),0) -> 0 | AK17: =_xlfn.IFS(AND(AND($AK$4>=$H17,$AK$4<=$O17)),4,AND(AND($AK$4>=$M17,$AK$4<=$N17)),3,AND(OR($AK$4<$M17,$AK$4>$N17)),0) -> 0 | AL17: =_xlfn.IFS(AND(AND($AL$4>=$H17,$AL$4<=$O17)),4,AND(AND($AL$4>=$M17,$AL$4<=$N17)),3,AND(OR($AL$4<$M17,$AL$4>$N17)),0) -> 0 | AM17: =_xlfn.IFS(AND(AND($AM$4>=$H17,$AM$4<=$O17)),4,AND(AND($AM$4>=$M17,$AM$4<=$N17)),3,AND(OR($AM$4<$M17,$AM$4>$N17)),0) -> 0 | AN17: =_xlfn.IFS(AND(AND($AN$4>=$H17,$AN$4<=$O17)),4,AND(AND($AN$4>=$M17,$AN$4<=$N17)),3,AND(OR($AN$4<$M17,$AN$4>$N17)),0) -> 0 | AO17: =_xlfn.IFS(AND(AND($AO$4>=$H17,$AO$4<=$O17)),4,AND(AND($AO$4>=$M17,$AO$4<=$N17)),3,AND(OR($AO$4<$M17,$AO$4>$N17)),0) -> 0 | AQ17: 2 | AR17: WAT_01 | BU17: =#REF! -> #REF!
B18: 14 | C18: 2 | D18: WATER | E18: WAT_02 | F18: Enhance sustainable lake conservation | H18: _ | I18: 1 | J18: 1 | M18: =H18 -> _ | N18: ='Project types'!$W$6 -> 2050 | O18: =IF(G18=1,(H18-1)+'Project types'!N19,IF(G18=2,H18-1,9999)) -> 9999 | P18: =_xlfn.IFS(AND(AND($P$4>=$H18,$P$4<=$O18)),4,AND(AND($P$4>=$M18,$P$4<=$N18)),3,AND(OR($P$4<$M18,$P$4>$N18)),0) -> 0 | Q18: =_xlfn.IFS(AND(AND($Q$4>=$H18,$Q$4<=$O18)),4,AND(AND($Q$4>=$M18,$Q$4<=$N18)),3,AND(OR($Q$4<$M18,$Q$4>$N18)),0) -> 0 | R18: =_xlfn.IFS(AND(AND($R$4>=$H18,$R$4<=$O18)),4,AND(AND($R$4>=$M18,$R$4<=$N18)),3,AND(OR($R$4<$M18,$R$4>$N18)),0) -> 0 | S18: =_xlfn.IFS(AND(AND($S$4>=$H18,$S$4<=$O18)),4,AND(AND($S$4>=$M18,$S$4<=$N18)),3,AND(OR($S$4<$M18,$S$4>$N18)),0) -> 0 | T18: =_xlfn.IFS(AND(AND($T$4>=$H18,$T$4<=$O18)),4,AND(AND($T$4>=$M18,$T$4<=$N18)),3,AND(OR($T$4<$M18,$T$4>$N18)),0) -> 0 | U18: =_xlfn.IFS(AND(AND($U$4>=$H18,$U$4<=$O18)),4,AND(AND($U$4>=$M18,$U$4<=$N18)),3,AND(OR($U$4<$M18,$U$4>$N18)),0) -> 0 | V18: =_xlfn.IFS(AND(AND($V$4>=$H18,$V$4<=$O18)),4,AND(AND($V$4>=$M18,$V$4<=$N18)),3,AND(OR($V$4<$M18,$V$4>$N18)),0) -> 0 | W18: =_xlfn.IFS(AND(AND($W$4>=$H18,$W$4<=$O18)),4,AND(AND($W$4>=$M18,$W$4<=$N18)),3,AND(OR($W$4<$M18,$W$4>$N18)),0) -> 0 | X18: =_xlfn.IFS(AND(AND($X$4>=$H18,$X$4<=$O18)),4,AND(AND($X$4>=$M18,$X$4<=$N18)),3,AND(OR($X$4<$M18,$X$4>$N18)),0) -> 0 | Y18: =_xlfn.IFS(AND(AND($Y$4>=$H18,$Y$4<=$O18)),4,AND(AND($Y$4>=$M18,$Y$4<=$N18)),3,AND(OR($Y$4<$M18,$Y$4>$N18)),0) -> 0 | Z18: =_xlfn.IFS(AND(AND($Z$4>=$H18,$Z$4<=$O18)),4,AND(AND($Z$4>=$M18,$Z$4<=$N18)),3,AND(OR($Z$4<$M18,$Z$4>$N18)),0) -> 0 | AA18: =_xlfn.IFS(AND(AND($AA$4>=$H18,$AA$4<=$O18)),4,AND(AND($AA$4>=$M18,$AA$4<=$N18)),3,AND(OR($AA$4<$M18,$AA$4>$N18)),0) -> 0 | AB18: =_xlfn.IFS(AND(AND($AB$4>=$H18,$AB$4<=$O18)),4,AND(AND($AB$4>=$M18,$AB$4<=$N18)),3,AND(OR($AB$4<$M18,$AB$4>$N18)),0) -> 0 | AC18: =_xlfn.IFS(AND(AND($AC$4>=$H18,$AC$4<=$O18)),4,AND(AND($AC$4>=$M18,$AC$4<=$N18)),3,AND(OR($AC$4<$M18,$AC$4>$N18)),0) -> 0 | AD18: =_xlfn.IFS(AND(AND($AD$4>=$H18,$AD$4<=$O18)),4,AND(AND($AD$4>=$M18,$AD$4<=$N18)),3,AND(OR($AD$4<$M18,$AD$4>$N18)),0) -> 0 | AE18: =_xlfn.IFS(AND(AND($AE$4>=$H18,$AE$4<=$O18)),4,AND(AND($AE$4>=$M18,$AE$4<=$N18)),3,AND(OR($AE$4<$M18,$AE$4>$N18)),0) -> 0 | AF18: =_xlfn.IFS(AND(AND($AF$4>=$H18,$AF$4<=$O18)),4,AND(AND($AF$4>=$M18,$AF$4<=$N18)),3,AND(OR($AF$4<$M18,$AF$4>$N18)),0) -> 0 | AG18: =_xlfn.IFS(AND(AND($AG$4>=$H18,$AG$4<=$O18)),4,AND(AND($AG$4>=$M18,$AG$4<=$N18)),3,AND(OR($AG$4<$M18,$AG$4>$N18)),0) -> 0 | AH18: =_xlfn.IFS(AND(AND($AH$4>=$H18,$AH$4<=$O18)),4,AND(AND($AH$4>=$M18,$AH$4<=$N18)),3,AND(OR($AH$4<$M18,$AH$4>$N18)),0) -> 0 | AI18: =_xlfn.IFS(AND(AND($AI$4>=$H18,$AI$4<=$O18)),4,AND(AND($AI$4>=$M18,$AI$4<=$N18)),3,AND(OR($AI$4<$M18,$AI$4>$N18)),0) -> 0 | AJ18: =_xlfn.IFS(AND(AND($AJ$4>=$H18,$AJ$4<=$O18)),4,AND(AND($AJ$4>=$M18,$AJ$4<=$N18)),3,AND(OR($AJ$4<$M18,$AJ$4>$N18)),0) -> 0 | AK18: =_xlfn.IFS(AND(AND($AK$4>=$H18,$AK$4<=$O18)),4,AND(AND($AK$4>=$M18,$AK$4<=$N18)),3,AND(OR($AK$4<$M18,$AK$4>$N18)),0) -> 0 | AL18: =_xlfn.IFS(AND(AND($AL$4>=$H18,$AL$4<=$O18)),4,AND(AND($AL$4>=$M18,$AL$4<=$N18)),3,AND(OR($AL$4<$M18,$AL$4>$N18)),0) -> 0 | AM18: =_xlfn.IFS(AND(AND($AM$4>=$H18,$AM$4<=$O18)),4,AND(AND($AM$4>=$M18,$AM$4<=$N18)),3,AND(OR($AM$4<$M18,$AM$4>$N18)),0) -> 0 | AN18: =_xlfn.IFS(AND(AND($AN$4>=$H18,$AN$4<=$O18)),4,AND(AND($AN$4>=$M18,$AN$4<=$N18)),3,AND(OR($AN$4<$M18,$AN$4>$N18)),0) -> 0 | AO18: =_xlfn.IFS(AND(AND($AO$4>=$H18,$AO$4<=$O18)),4,AND(AND($AO$4>=$M18,$AO$4<=$N18)),3,AND(OR($AO$4<$M18,$AO$4>$N18)),0) -> 0 | AQ18: 2 | AR18: WAT_02 | BU18: =#REF! -> #REF!
B19: 15 | C19: 2 | D19: WATER | E19: WAT_03 | F19: Enhance sustainable river conservation | H19: _ | I19: 1 | J19: 1 | M19: =H19 -> _ | N19: ='Project types'!$W$6 -> 2050 | O19: =IF(G19=1,(H19-1)+'Project types'!N20,IF(G19=2,H19-1,9999)) -> 9999 | P19: =_xlfn.IFS(AND(AND($P$4>=$H19,$P$4<=$O19)),4,AND(AND($P$4>=$M19,$P$4<=$N19)),3,AND(OR($P$4<$M19,$P$4>$N19)),0) -> 0 | Q19: =_xlfn.IFS(AND(AND($Q$4>=$H19,$Q$4<=$O19)),4,AND(AND($Q$4>=$M19,$Q$4<=$N19)),3,AND(OR($Q$4<$M19,$Q$4>$N19)),0) -> 0 | R19: =_xlfn.IFS(AND(AND($R$4>=$H19,$R$4<=$O19)),4,AND(AND($R$4>=$M19,$R$4<=$N19)),3,AND(OR($R$4<$M19,$R$4>$N19)),0) -> 0 | S19: =_xlfn.IFS(AND(AND($S$4>=$H19,$S$4<=$O19)),4,AND(AND($S$4>=$M19,$S$4<=$N19)),3,AND(OR($S$4<$M19,$S$4>$N19)),0) -> 0 | T19: =_xlfn.IFS(AND(AND($T$4>=$H19,$T$4<=$O19)),4,AND(AND($T$4>=$M19,$T$4<=$N19)),3,AND(OR($T$4<$M19,$T$4>$N19)),0) -> 0 | U19: =_xlfn.IFS(AND(AND($U$4>=$H19,$U$4<=$O19)),4,AND(AND($U$4>=$M19,$U$4<=$N19)),3,AND(OR($U$4<$M19,$U$4>$N19)),0) -> 0 | V19: =_xlfn.IFS(AND(AND($V$4>=$H19,$V$4<=$O19)),4,AND(AND($V$4>=$M19,$V$4<=$N19)),3,AND(OR($V$4<$M19,$V$4>$N19)),0) -> 0 | W19: =_xlfn.IFS(AND(AND($W$4>=$H19,$W$4<=$O19)),4,AND(AND($W$4>=$M19,$W$4<=$N19)),3,AND(OR($W$4<$M19,$W$4>$N19)),0) -> 0 | X19: =_xlfn.IFS(AND(AND($X$4>=$H19,$X$4<=$O19)),4,AND(AND($X$4>=$M19,$X$4<=$N19)),3,AND(OR($X$4<$M19,$X$4>$N19)),0) -> 0 | Y19: =_xlfn.IFS(AND(AND($Y$4>=$H19,$Y$4<=$O19)),4,AND(AND($Y$4>=$M19,$Y$4<=$N19)),3,AND(OR($Y$4<$M19,$Y$4>$N19)),0) -> 0 | Z19: =_xlfn.IFS(AND(AND($Z$4>=$H19,$Z$4<=$O19)),4,AND(AND($Z$4>=$M19,$Z$4<=$N19)),3,AND(OR($Z$4<$M19,$Z$4>$N19)),0) -> 0 | AA19: =_xlfn.IFS(AND(AND($AA$4>=$H19,$AA$4<=$O19)),4,AND(AND($AA$4>=$M19,$AA$4<=$N19)),3,AND(OR($AA$4<$M19,$AA$4>$N19)),0) -> 0 | AB19: =_xlfn.IFS(AND(AND($AB$4>=$H19,$AB$4<=$O19)),4,AND(AND($AB$4>=$M19,$AB$4<=$N19)),3,AND(OR($AB$4<$M19,$AB$4>$N19)),0) -> 0 | AC19: =_xlfn.IFS(AND(AND($AC$4>=$H19,$AC$4<=$O19)),4,AND(AND($AC$4>=$M19,$AC$4<=$N19)),3,AND(OR($AC$4<$M19,$AC$4>$N19)),0) -> 0 | AD19: =_xlfn.IFS(AND(AND($AD$4>=$H19,$AD$4<=$O19)),4,AND(AND($AD$4>=$M19,$AD$4<=$N19)),3,AND(OR($AD$4<$M19,$AD$4>$N19)),0) -> 0 | AE19: =_xlfn.IFS(AND(AND($AE$4>=$H19,$AE$4<=$O19)),4,AND(AND($AE$4>=$M19,$AE$4<=$N19)),3,AND(OR($AE$4<$M19,$AE$4>$N19)),0) -> 0 | AF19: =_xlfn.IFS(AND(AND($AF$4>=$H19,$AF$4<=$O19)),4,AND(AND($AF$4>=$M19,$AF$4<=$N19)),3,AND(OR($AF$4<$M19,$AF$4>$N19)),0) -> 0 | AG19: =_xlfn.IFS(AND(AND($AG$4>=$H19,$AG$4<=$O19)),4,AND(AND($AG$4>=$M19,$AG$4<=$N19)),3,AND(OR($AG$4<$M19,$AG$4>$N19)),0) -> 0 | AH19: =_xlfn.IFS(AND(AND($AH$4>=$H19,$AH$4<=$O19)),4,AND(AND($AH$4>=$M19,$AH$4<=$N19)),3,AND(OR($AH$4<$M19,$AH$4>$N19)),0) -> 0 | AI19: =_xlfn.IFS(AND(AND($AI$4>=$H19,$AI$4<=$O19)),4,AND(AND($AI$4>=$M19,$AI$4<=$N19)),3,AND(OR($AI$4<$M19,$AI$4>$N19)),0) -> 0 | AJ19: =_xlfn.IFS(AND(AND($AJ$4>=$H19,$AJ$4<=$O19)),4,AND(AND($AJ$4>=$M19,$AJ$4<=$N19)),3,AND(OR($AJ$4<$M19,$AJ$4>$N19)),0) -> 0 | AK19: =_xlfn.IFS(AND(AND($AK$4>=$H19,$AK$4<=$O19)),4,AND(AND($AK$4>=$M19,$AK$4<=$N19)),3,AND(OR($AK$4<$M19,$AK$4>$N19)),0) -> 0 | AL19: =_xlfn.IFS(AND(AND($AL$4>=$H19,$AL$4<=$O19)),4,AND(AND($AL$4>=$M19,$AL$4<=$N19)),3,AND(OR($AL$4<$M19,$AL$4>$N19)),0) -> 0 | AM19: =_xlfn.IFS(AND(AND($AM$4>=$H19,$AM$4<=$O19)),4,AND(AND($AM$4>=$M19,$AM$4<=$N19)),3,AND(OR($AM$4<$M19,$AM$4>$N19)),0) -> 0 | AN19: =_xlfn.IFS(AND(AND($AN$4>=$H19,$AN$4<=$O19)),4,AND(AND($AN$4>=$M19,$AN$4<=$N19)),3,AND(OR($AN$4<$M19,$AN$4>$N19)),0) -> 0 | AO19: =_xlfn.IFS(AND(AND($AO$4>=$H19,$AO$4<=$O19)),4,AND(AND($AO$4>=$M19,$AO$4<=$N19)),3,AND(OR($AO$4<$M19,$AO$4>$N19)),0) -> 0 | AQ19: 2 | AR19: WAT_03 | BU19: =#REF! -> #REF!
B20: 16 | C20: 2 | D20: WATER | E20: WAT_04 | F20: Enhance aquifer conservation, infiltration and recharge | H20: _ | I20: 0.1 | J20: 1 | M20: =H20 -> _ | N20: ='Project types'!$W$6 -> 2050 | O20: =IF(G20=1,(H20-1)+'Project types'!N21,IF(G20=2,H20-1,9999)) -> 9999 | P20: =_xlfn.IFS(AND(AND($P$4>=$H20,$P$4<=$O20)),4,AND(AND($P$4>=$M20,$P$4<=$N20)),3,AND(OR($P$4<$M20,$P$4>$N20)),0) -> 0 | Q20: =_xlfn.IFS(AND(AND($Q$4>=$H20,$Q$4<=$O20)),4,AND(AND($Q$4>=$M20,$Q$4<=$N20)),3,AND(OR($Q$4<$M20,$Q$4>$N20)),0) -> 0 | R20: =_xlfn.IFS(AND(AND($R$4>=$H20,$R$4<=$O20)),4,AND(AND($R$4>=$M20,$R$4<=$N20)),3,AND(OR($R$4<$M20,$R$4>$N20)),0) -> 0 | S20: =_xlfn.IFS(AND(AND($S$4>=$H20,$S$4<=$O20)),4,AND(AND($S$4>=$M20,$S$4<=$N20)),3,AND(OR($S$4<$M20,$S$4>$N20)),0) -> 0 | T20: =_xlfn.IFS(AND(AND($T$4>=$H20,$T$4<=$O20)),4,AND(AND($T$4>=$M20,$T$4<=$N20)),3,AND(OR($T$4<$M20,$T$4>$N20)),0) -> 0 | U20: =_xlfn.IFS(AND(AND($U$4>=$H20,$U$4<=$O20)),4,AND(AND($U$4>=$M20,$U$4<=$N20)),3,AND(OR($U$4<$M20,$U$4>$N20)),0) -> 0 | V20: =_xlfn.IFS(AND(AND($V$4>=$H20,$V$4<=$O20)),4,AND(AND($V$4>=$M20,$V$4<=$N20)),3,AND(OR($V$4<$M20,$V$4>$N20)),0) -> 0 | W20: =_xlfn.IFS(AND(AND($W$4>=$H20,$W$4<=$O20)),4,AND(AND($W$4>=$M20,$W$4<=$N20)),3,AND(OR($W$4<$M20,$W$4>$N20)),0) -> 0 | X20: =_xlfn.IFS(AND(AND($X$4>=$H20,$X$4<=$O20)),4,AND(AND($X$4>=$M20,$X$4<=$N20)),3,AND(OR($X$4<$M20,$X$4>$N20)),0) -> 0 | Y20: =_xlfn.IFS(AND(AND($Y$4>=$H20,$Y$4<=$O20)),4,AND(AND($Y$4>=$M20,$Y$4<=$N20)),3,AND(OR($Y$4<$M20,$Y$4>$N20)),0) -> 0 | Z20: =_xlfn.IFS(AND(AND($Z$4>=$H20,$Z$4<=$O20)),4,AND(AND($Z$4>=$M20,$Z$4<=$N20)),3,AND(OR($Z$4<$M20,$Z$4>$N20)),0) -> 0 | AA20: =_xlfn.IFS(AND(AND($AA$4>=$H20,$AA$4<=$O20)),4,AND(AND($AA$4>=$M20,$AA$4<=$N20)),3,AND(OR($AA$4<$M20,$AA$4>$N20)),0) -> 0 | AB20: =_xlfn.IFS(AND(AND($AB$4>=$H20,$AB$4<=$O20)),4,AND(AND($AB$4>=$M20,$AB$4<=$N20)),3,AND(OR($AB$4<$M20,$AB$4>$N20)),0) -> 0 | AC20: =_xlfn.IFS(AND(AND($AC$4>=$H20,$AC$4<=$O20)),4,AND(AND($AC$4>=$M20,$AC$4<=$N20)),3,AND(OR($AC$4<$M20,$AC$4>$N20)),0) -> 0 | AD20: =_xlfn.IFS(AND(AND($AD$4>=$H20,$AD$4<=$O20)),4,AND(AND($AD$4>=$M20,$AD$4<=$N20)),3,AND(OR($AD$4<$M20,$AD$4>$N20)),0) -> 0 | AE20: =_xlfn.IFS(AND(AND($AE$4>=$H20,$AE$4<=$O20)),4,AND(AND($AE$4>=$M20,$AE$4<=$N20)),3,AND(OR($AE$4<$M20,$AE$4>$N20)),0) -> 0 | AF20: =_xlfn.IFS(AND(AND($AF$4>=$H20,$AF$4<=$O20)),4,AND(AND($AF$4>=$M20,$AF$4<=$N20)),3,AND(OR($AF$4<$M20,$AF$4>$N20)),0) -> 0 | AG20: =_xlfn.IFS(AND(AND($AG$4>=$H20,$AG$4<=$O20)),4,AND(AND($AG$4>=$M20,$AG$4<=$N20)),3,AND(OR($AG$4<$M20,$AG$4>$N20)),0) -> 0 | AH20: =_xlfn.IFS(AND(AND($AH$4>=$H20,$AH$4<=$O20)),4,AND(AND($AH$4>=$M20,$AH$4<=$N20)),3,AND(OR($AH$4<$M20,$AH$4>$N20)),0) -> 0 | AI20: =_xlfn.IFS(AND(AND($AI$4>=$H20,$AI$4<=$O20)),4,AND(AND($AI$4>=$M20,$AI$4<=$N20)),3,AND(OR($AI$4<$M20,$AI$4>$N20)),0) -> 0 | AJ20: =_xlfn.IFS(AND(AND($AJ$4>=$H20,$AJ$4<=$O20)),4,AND(AND($AJ$4>=$M20,$AJ$4<=$N20)),3,AND(OR($AJ$4<$M20,$AJ$4>$N20)),0) -> 0 | AK20: =_xlfn.IFS(AND(AND($AK$4>=$H20,$AK$4<=$O20)),4,AND(AND($AK$4>=$M20,$AK$4<=$N20)),3,AND(OR($AK$4<$M20,$AK$4>$N20)),0) -> 0 | AL20: =_xlfn.IFS(AND(AND($AL$4>=$H20,$AL$4<=$O20)),4,AND(AND($AL$4>=$M20,$AL$4<=$N20)),3,AND(OR($AL$4<$M20,$AL$4>$N20)),0) -> 0 | AM20: =_xlfn.IFS(AND(AND($AM$4>=$H20,$AM$4<=$O20)),4,AND(AND($AM$4>=$M20,$AM$4<=$N20)),3,AND(OR($AM$4<$M20,$AM$4>$N20)),0) -> 0 | AN20: =_xlfn.IFS(AND(AND($AN$4>=$H20,$AN$4<=$O20)),4,AND(AND($AN$4>=$M20,$AN$4<=$N20)),3,AND(OR($AN$4<$M20,$AN$4>$N20)),0) -> 0 | AO20: =_xlfn.IFS(AND(AND($AO$4>=$H20,$AO$4<=$O20)),4,AND(AND($AO$4>=$M20,$AO$4<=$N20)),3,AND(OR($AO$4<$M20,$AO$4>$N20)),0) -> 0 | AQ20: 2 | AR20: WAT_04 | BU20: =#REF! -> #REF!
